Workbook

Sheet FSC
B2: CW | C2: 46023 | D2: 46054 | E2: 46082 | F2: 46113 | G2: 46143 | H2: 46174 | I2: 46204 | J2: 46235 | K2: 46266 | L2: 46296 | M2: 46327 | N2: 46357 | O2: TOTAL | Q2: CW | R2: 46023 | S2: 46054 | T2: 46082 | U2: 46113 | V2: 46143 | W2: 46174 | X2: 46204 | Y2: 46235 | Z2: 46266 | AA2: 46296 | AB2: 46327 | AC2: 46357 | AD2: 46023 | AE2: TOTAL
B3: Print | C3: 0 | D3: 0 | E3: 0 | F3: 0 | G3: 0 | H3: 0 | I3: 0 | J3: 0 | K3: 0 | L3: 0 | M3: 0 | N3: 0 | O3: =SUM(C3:N3) -> 0 | Q3: Print | R3: 0 | S3: 0 | T3: 0 | U3: 0 | V3: 0 | W3: 0 | X3: 0 | Y3: 0 | Z3: 0 | AA3: 0 | AB3: 0 | AC3: 0 | AE3: =SUM(R3:AC3) -> 0
B6: CW | C6: 46023 | D6: 46054 | E6: 46082 | F6: 46113 | G6: 46143 | H6: 46174 | I6: 46204 | J6: 46235 | K6: 46266 | L6: 46296 | M6: 46327 | N6: 46357 | O6: TOTAL | Q6: CW | R6: 46023 | S6: 46054 | T6: 46082 | U6: 46113 | V6: 46143 | W6: 46174 | X6: 46204 | Y6: 46235 | Z6: 46266 | AA6: 46296 | AB6: 46327 | AC6: 46357 | AD6: 46023 | AE6: TOTAL
B7: IP | C7: 0 | D7: 0 | E7: 0 | F7: 0 | G7: 0 | H7: 0 | I7: 0 | J7: 0 | K7: 0 | L7: 0 | M7: 0 | N7: 0 | O7: =SUM(C7:N7) -> 0 | Q7: IP | R7: =C7/0.06 -> 0 | S7: =D7/0.06 -> 0 | T7: =E7/0.06 -> 0 | U7: =F7/0.06 -> 0 | V7: =G7/0.06 -> 0 | W7: =H7/0.06 -> 0 | X7: =I7/0.06 -> 0 | Y7: =J7/0.06 -> 0 | ... AC7: =N7/0.06 -> 0 | AE7: =SUM(R7:AC7) -> 0
B10: FSC MISTO | C10: 46023 | D10: 46054 | E10: 46082 | F10: 46113 | G10: 46143 | H10: 46174 | I10: 46204 | J10: 46235 | K10: 46266 | L10: 46296 | M10: 46327 | N10: 46357 | O10: TOTAL | Q10: MISTO | R10: 46023 | S10: 46054 | T10: 46082 | U10: 46113 | V10: 46143 | W10: 46174 | X10: 46204 | Y10: 46235 | Z10: 46266 | AA10: 46296 | AB10: 46327 | AC10: 46357 | AD10: 46023 | AE10: TOTAL
B11: Print | C11: =SUMIF(Reunido!$BQ:$BQ,$B$11,Reunido!E:E) -> 267059 | D11: =SUMIF(Reunido!$BQ:$BQ,$B$11,Reunido!J:J) -> 88509 | E11: =SUMIF(Reunido!$BQ:$BQ,$B$11,Reunido!O:O) -> 584966 | F11: =SUMIF(Reunido!$BQ:$BQ,$B$11,Reunido!T:T) -> 720393 | G11: =SUMIF(Reunido!$BQ:$BQ,$B$11,Reunido!Y:Y) -> 373064 | H11: =SUMIF(Reunido!$BQ:$BQ,$B$11,Reunido!AD:AD) -> 626051 | I11: =SUMIF(Reunido!$BQ:$BQ,$B$11,Reunido!AI:AI) -> 0 | J11: =SUMIF(Reunido!$BQ:$BQ,$B$11,Reunido!AN:AN) -> 0 | K11: =SUMIF(Reunido!$BQ:$BQ,$B$11,Reunido!AS:AS) -> 0 | L11: =SUMIF(Reunido!$BQ:$BQ,$B$11,Reunido!AX:AX) -> 0 | M11: =SUMIF(Reunido!$BQ:$BQ,$B$11,Reunido!BH:BH) -> 0 | N11: =SUMIF(Reunido!$BQ:$BQ,$B$11,Reunido!BH:BH) -> 0 | O11: =SUM(C11:N11) -> 2660042 | Q11: Print | R11: =C11/0.068 -> 3927338.2 | S11: =D11/0.068 -> 1301602.9 | T11: =E11/0.068 -> 8602441.2 | U11: =F11/0.068 -> 10594015 | V11: =G11/0.068 -> 5486235.3 | W11: =H11/0.068 -> 9206632.4 | X11: =I11/0.068 -> 0 | Y11: =J11/0.068 -> 0 | ... AC11: =N11/0.068 -> 0 | AD11: 0 | AE11: =SUM(R11:AC11) -> 39118265
B14: FSC MISTO | C14: 46023 | D14: 46054 | E14: 46082 | F14: 46113 | G14: 46143 | H14: 46174 | I14: 46204 | J14: 46235 | K14: 46266 | L14: 46296 | M14: 46327 | N14: 46357 | O14: TOTAL | Q14: MISTO | R14: 46023 | S14: 46054 | T14: 46082 | U14: 46113 | V14: 46143 | W14: 46174 | X14: 46204 | Y14: 46235 | Z14: 46266 | AA14: 46296 | AB14: 46327 | AC14: 46357 | AD14: 46023 | AE14: TOTAL
B15: FF | C15: =SUMIF(Reunido!$BQ:$BQ,$B$15,Reunido!E:E) -> 118340 | D15: =SUMIF(Reunido!$BQ:$BQ,$B$15,Reunido!J:J) -> 45411 | E15: =SUMIF(Reunido!$BQ:$BQ,$B$15,Reunido!O:O) -> 144702 | F15: =SUMIF(Reunido!$BQ:$BQ,$B$15,Reunido!T:T) -> 216929 | G15: =SUMIF(Reunido!$BQ:$BQ,$B$15,Reunido!Y:Y) -> 63804 | H15: =SUMIF(Reunido!$BQ:$BQ,$B$15,Reunido!AD:AD) -> 98927 | I15: =SUMIF(Reunido!$BQ:$BQ,$B$15,Reunido!AI:AI) -> 0 | J15: =SUMIF(Reunido!$BQ:$BQ,$B$15,Reunido!AN:AN) -> 0 | K15: =SUMIF(Reunido!$BQ:$BQ,$B$15,Reunido!AS:AS) -> 0 | L15: =SUMIF(Reunido!$BQ:$BQ,$B$15,Reunido!AX:AX) -> 0 | M15: =SUMIF(Reunido!$BQ:$BQ,$B$15,Reunido!BC:BC) -> 0 | N15: =SUMIF(Reunido!$BQ:$BQ,$B$15,Reunido!BH:BH) -> 0 | O15: =SUM(C15:N15) -> 688113 | Q15: FF | R15: =SUMIFS('PAPER BASE'!$G:$G, 'PAPER BASE'!$B:$B, "*MLTV01*", 'PAPER BASE'!$C:$C, "Finish Foils", 'PAPER BASE'!$I:$I, R14)/ 0.04+SUMIFS('PAPER BASE'!$G:$G, 'PAPER BASE'!$B:$B, "*MUNK04*", 'PAPER BASE'!$C:$C, "Finish Foils", 'PAPER BASE'!$I:$I, R14)/ 0.07+SUMIFS('PAPER BASE'!$G:$G, 'PAPER BASE'!$B:$B, "*KING01*", 'PAPER BASE'!$C:$C, "Finish Foils", 'PAPER BASE'!$I:$I, R14)/ 0.07 -> 2454992.9 | S15: =SUMIFS('PAPER BASE'!$G:$G, 'PAPER BASE'!$B:$B, "*MLTV01*", 'PAPER BASE'!$C:$C, "Finish Foils", 'PAPER BASE'!$I:$I, S14)/ 0.04+SUMIFS('PAPER BASE'!$G:$G, 'PAPER BASE'!$B:$B, "*MUNK04*", 'PAPER BASE'!$C:$C, "Finish Foils", 'PAPER BASE'!$I:$I, S14)/ 0.07+SUMIFS('PAPER BASE'!$G:$G, 'PAPER BASE'!$B:$B, "*KING01*", 'PAPER BASE'!$C:$C, "Finish Foils", 'PAPER BASE'!$I:$I, S14)/ 0.07 -> 1135275 | T15: =SUMIFS('PAPER BASE'!$G:$G, 'PAPER BASE'!$B:$B, "*MLTV01*", 'PAPER BASE'!$C:$C, "Finish Foils", 'PAPER BASE'!$I:$I, T14)/ 0.04+SUMIFS('PAPER BASE'!$G:$G, 'PAPER BASE'!$B:$B, "*MUNK04*", 'PAPER BASE'!$C:$C, "Finish Foils", 'PAPER BASE'!$I:$I, T14)/ 0.07+SUMIFS('PAPER BASE'!$G:$G, 'PAPER BASE'!$B:$B, "*KING01*", 'PAPER BASE'!$C:$C, "Finish Foils", 'PAPER BASE'!$I:$I, T14)/ 0.07 -> 3098914.3 | U15: =SUMIFS('PAPER BASE'!$G:$G, 'PAPER BASE'!$B:$B, "*MLTV01*", 'PAPER BASE'!$C:$C, "Finish Foils", 'PAPER BASE'!$I:$I, U14)/ 0.04+SUMIFS('PAPER BASE'!$G:$G, 'PAPER BASE'!$B:$B, "*MUNK04*", 'PAPER BASE'!$C:$C, "Finish Foils", 'PAPER BASE'!$I:$I, U14)/ 0.07+SUMIFS('PAPER BASE'!$G:$G, 'PAPER BASE'!$B:$B, "*KING01*", 'PAPER BASE'!$C:$C, "Finish Foils", 'PAPER BASE'!$I:$I, U14)/ 0.07 -> 3856110.7 | V15: =SUMIFS('PAPER BASE'!$G:$G, 'PAPER BASE'!$B:$B, "*MLTV01*", 'PAPER BASE'!$C:$C, "Finish Foils", 'PAPER BASE'!$I:$I, V14)/ 0.04+SUMIFS('PAPER BASE'!$G:$G, 'PAPER BASE'!$B:$B, "*MUNK04*", 'PAPER BASE'!$C:$C, "Finish Foils", 'PAPER BASE'!$I:$I, V14)/ 0.07+SUMIFS('PAPER BASE'!$G:$G, 'PAPER BASE'!$B:$B, "*KING01*", 'PAPER BASE'!$C:$C, "Finish Foils", 'PAPER BASE'!$I:$I, V14)/ 0.07 -> 2153121.4 | W15: =SUMIFS('PAPER BASE'!$G:$G, 'PAPER BASE'!$B:$B, "*MLTV01*", 'PAPER BASE'!$C:$C, "Finish Foils", 'PAPER BASE'!$I:$I, W14)/ 0.04+SUMIFS('PAPER BASE'!$G:$G, 'PAPER BASE'!$B:$B, "*MUNK04*", 'PAPER BASE'!$C:$C, "Finish Foils", 'PAPER BASE'!$I:$I, W14)/ 0.07+SUMIFS('PAPER BASE'!$G:$G, 'PAPER BASE'!$B:$B, "*KING01*", 'PAPER BASE'!$C:$C, "Finish Foils", 'PAPER BASE'!$I:$I, W14)/ 0.07 -> 1672539.3 | X15: =SUMIFS('PAPER BASE'!$G:$G, 'PAPER BASE'!$B:$B, "*MLTV01*", 'PAPER BASE'!$C:$C, "Finish Foils", 'PAPER BASE'!$I:$I, X14)/ 0.04+SUMIFS('PAPER BASE'!$G:$G, 'PAPER BASE'!$B:$B, "*MUNK04*", 'PAPER BASE'!$C:$C, "Finish Foils", 'PAPER BASE'!$I:$I, X14)/ 0.07+SUMIFS('PAPER BASE'!$G:$G, 'PAPER BASE'!$B:$B, "*KING01*", 'PAPER BASE'!$C:$C, "Finish Foils", 'PAPER BASE'!$I:$I, X14)/ 0.07 -> 0 | Y15: =SUMIFS('PAPER BASE'!$G:$G, 'PAPER BASE'!$B:$B, "*MLTV01*", 'PAPER BASE'!$C:$C, "Finish Foils", 'PAPER BASE'!$I:$I, Y14)/ 0.04+SUMIFS('PAPER BASE'!$G:$G, 'PAPER BASE'!$B:$B, "*MUNK04*", 'PAPER BASE'!$C:$C, "Finish Foils", 'PAPER BASE'!$I:$I, Y14)/ 0.07+SUMIFS('PAPER BASE'!$G:$G, 'PAPER BASE'!$B:$B, "*KING01*", 'PAPER BASE'!$C:$C, "Finish Foils", 'PAPER BASE'!$I:$I, Y14)/ 0.07 -> 0 | ... AC15: =SUMIFS('PAPER BASE'!$G:$G, 'PAPER BASE'!$B:$B, "*MLTV01*", 'PAPER BASE'!$C:$C, "Finish Foils", 'PAPER BASE'!$I:$I, AC14)/ 0.04+SUMIFS('PAPER BASE'!$G:$G, 'PAPER BASE'!$B:$B, "*MUNK04*", 'PAPER BASE'!$C:$C, "Finish Foils", 'PAPER BASE'!$I:$I, AC14)/ 0.07+SUMIFS('PAPER BASE'!$G:$G, 'PAPER BASE'!$B:$B, "*KING01*", 'PAPER BASE'!$C:$C, "Finish Foils", 'PAPER BASE'!$I:$I, AC14)/ 0.07 -> 0 | AD15: 0 | AE15: =SUM(R15:AC15) -> 14370954
B18: FSC MISTO | C18: 46023 | D18: 46054 | E18: 46082 | F18: 46113 | G18: 46143 | H18: 46174 | I18: 46204 | J18: 46235 | K18: 46266 | L18: 46296 | M18: 46327 | N18: 46357 | O18: TOTAL | Q18: FSC MISTO | R18: 46023 | S18: 46054 | T18: 46082 | U18: 46113 | V18: 46143 | W18: 46174 | X18: 46204 | Y18: 46235 | Z18: 46266 | AA18: 46296 | AB18: 46327 | AC18: 46357 | AD18: 46023 | AE18: TOTAL
B19: IP | C19: =SUMIF(Reunido!$BQ:$BQ,$B$19,Reunido!E:E) -> 77515 | D19: =SUMIF(Reunido!$BQ:$BQ,$B$19,Reunido!J:J) -> 260289 | E19: =SUMIF(Reunido!$BQ:$BQ,$B$19,Reunido!O:O) -> 380338 | F19: =SUMIF(Reunido!$BQ:$BQ,$B$19,Reunido!T:T) -> 211316 | G19: =SUMIF(Reunido!$BQ:$BQ,$B$19,Reunido!Y:Y) -> 335919 | H19: =SUMIF(Reunido!$BQ:$BQ,$B$19,Reunido!AD:AD) -> 90455 | I19: =SUMIF(Reunido!$BQ:$BQ,$B$19,Reunido!AI:AI) -> 0 | J19: =SUMIF(Reunido!$BQ:$BQ,$B$19,Reunido!AN:AN) -> 0 | K19: =SUMIF(Reunido!$BQ:$BQ,$B$19,Reunido!AS:AS) -> 0 | L19: =SUMIF(Reunido!$BQ:$BQ,$B$19,Reunido!AX:AX) -> 0 | M19: =SUMIF(Reunido!$BQ:$BQ,$B$19,Reunido!BC:BC) -> 0 | N19: =SUMIF(Reunido!$BQ:$BQ,$B$19,Reunido!BH:BH) -> 0 | O19: =SUM(C19:N19) -> 1355832 | Q19: IP | R19: =C19/0.08 -> 968937.5 | S19: =D19/0.08 -> 3253612.5 | T19: =E19/0.08 -> 4754225 | U19: =F19/0.08 -> 2641450 | V19: =G19/0.08 -> 4198987.5 | W19: =H19/0.08 -> 1130687.5 | X19: =I19/0.08 -> 0 | Y19: =J19/0.08 -> 0 | ... AC19: =N19/0.08 -> 0 | AE19: =SUM(R19:AC19) -> 16947900
B22: KG | C22: 46023 | D22: 46054 | E22: 46082 | F22: 46113 | G22: 46143 | H22: 46174 | I22: 46204 | J22: 46235 | K22: 46266 | L22: 46296 | M22: 46327 | N22: 46357 | O22: TOTAL | R22: 46023 | S22: 46054 | T22: 46082 | U22: 46113 | V22: 46143 | W22: 46174 | X22: 46204 | Y22: 46235 | Z22: 46266 | AA22: 46296 | AB22: 46327 | AC22: 46357 | AD22: janeiro | AE22: TOTAL
B23: Print | C23: =SUMIF($B$2:$B$21,$B23,C$2:C$21) -> 267059 | D23: =SUMIF($B$2:$B$21,$B23,D$2:D$21) -> 88509 | E23: =SUMIF($B$2:$B$21,$B23,E$2:E$21) -> 584966 | F23: =SUMIF($B$2:$B$21,$B23,F$2:F$21) -> 720393 | G23: =SUMIF($B$2:$B$21,$B23,G$2:G$21) -> 373064 | H23: =SUMIF($B$2:$B$21,$B23,H$2:H$21) -> 626051 | I23: =SUMIF($B$2:$B$21,$B23,I$2:I$21) -> 0 | J23: =SUMIF($B$2:$B$21,$B23,J$2:J$21) -> 0 | ... N23: =SUMIF($B$2:$B$21,$B23,N$2:N$21) -> 0 | O23: =SUM(C23:N23) -> 2660042 | Q23: Print | R23: =SUMIF($B$2:$B$21,$B23,R$2:R$21) -> 3927338.2 | S23: =SUMIF($B$2:$B$21,$B23,S$2:S$21) -> 1301602.9 | T23: =SUMIF($B$2:$B$21,$B23,T$2:T$21) -> 8602441.2 | U23: =SUMIF($B$2:$B$21,$B23,U$2:U$21) -> 10594015 | V23: =SUMIF($B$2:$B$21,$B23,V$2:V$21) -> 5486235.3 | W23: =SUMIF($B$2:$B$21,$B23,W$2:W$21) -> 9206632.4 | X23: =SUMIF($B$2:$B$21,$B23,X$2:X$21) -> 0 | Y23: =SUMIF($B$2:$B$21,$B23,Y$2:Y$21) -> 0 | ... AC23: =SUMIF($B$2:$B$21,$B23,AC$2:AC$21) -> 0 | AE23: =SUM(R23:AC23) -> 39118265
B24: FF | C24: =SUMIF($B$2:$B$21,$B24,C$2:C$21) -> 118340 | D24: =SUMIF($B$2:$B$21,$B24,D$2:D$21) -> 45411 | E24: =SUMIF($B$2:$B$21,$B24,E$2:E$21) -> 144702 | F24: =SUMIF($B$2:$B$21,$B24,F$2:F$21) -> 216929 | G24: =SUMIF($B$2:$B$21,$B24,G$2:G$21) -> 63804 | H24: =SUMIF($B$2:$B$21,$B24,H$2:H$21) -> 98927 | I24: =SUMIF($B$2:$B$21,$B24,I$2:I$21) -> 0 | J24: =SUMIF($B$2:$B$21,$B24,J$2:J$21) -> 0 | ... N24: =SUMIF($B$2:$B$21,$B24,N$2:N$21) -> 0 | O24: =SUM(C24:N24) -> 688113 | Q24: FF | R24: =SUMIF($B$2:$B$21,$B24,R$2:R$21) -> 2454992.9 | S24: =SUMIF($B$2:$B$21,$B24,S$2:S$21) -> 1135275 | T24: =SUMIF($B$2:$B$21,$B24,T$2:T$21) -> 3098914.3 | U24: =SUMIF($B$2:$B$21,$B24,U$2:U$21) -> 3856110.7 | V24: =SUMIF($B$2:$B$21,$B24,V$2:V$21) -> 2153121.4 | W24: =SUMIF($B$2:$B$21,$B24,W$2:W$21) -> 1672539.3 | X24: =SUMIF($B$2:$B$21,$B24,X$2:X$21) -> 0 | Y24: =SUMIF($B$2:$B$21,$B24,Y$2:Y$21) -> 0 | ... AC24: =SUMIF($B$2:$B$21,$B24,AC$2:AC$21) -> 0 | AE24: =SUM(R24:AC24) -> 14370954
B25: IP | C25: =SUMIF($B$2:$B$21,$B25,C$2:C$21) -> 77515 | D25: =SUMIF($B$2:$B$21,$B25,D$2:D$21) -> 260289 | E25: =SUMIF($B$2:$B$21,$B25,E$2:E$21) -> 380338 | F25: =SUMIF($B$2:$B$21,$B25,F$2:F$21) -> 211316 | G25: =SUMIF($B$2:$B$21,$B25,G$2:G$21) -> 335919 | H25: =SUMIF($B$2:$B$21,$B25,H$2:H$21) -> 90455 | I25: =SUMIF($B$2:$B$21,$B25,I$2:I$21) -> 0 | J25: =SUMIF($B$2:$B$21,$B25,J$2:J$21) -> 0 | ... N25: =SUMIF($B$2:$B$21,$B25,N$2:N$21) -> 0 | O25: =SUM(C25:N25) -> 1355832 | Q25: IP | R25: =SUMIF($B$2:$B$21,$B25,R$2:R$21) -> 968937.5 | S25: =SUMIF($B$2:$B$21,$B25,S$2:S$21) -> 3253612.5 | T25: =SUMIF($B$2:$B$21,$B25,T$2:T$21) -> 4754225 | U25: =SUMIF($B$2:$B$21,$B25,U$2:U$21) -> 2641450 | V25: =SUMIF($B$2:$B$21,$B25,V$2:V$21) -> 4198987.5 | W25: =SUMIF($B$2:$B$21,$B25,W$2:W$21) -> 1130687.5 | X25: =SUMIF($B$2:$B$21,$B25,X$2:X$21) -> 0 | Y25: =SUMIF($B$2:$B$21,$B25,Y$2:Y$21) -> 0 | ... AC25: =SUMIF($B$2:$B$21,$B25,AC$2:AC$21) -> 0 | AE25: =SUM(R25:AC25) -> 16947900
B26: Total | C26: =SUM(C23:C25) -> 462914 | D26: =SUM(D23:D25) -> 394209 | E26: =SUM(E23:E25) -> 1110006 | F26: =SUM(F23:F25) -> 1148638 | G26: =SUM(G23:G25) -> 772787 | H26: =SUM(H23:H25) -> 815433 | I26: =SUM(I23:I25) -> 0 | J26: =SUM(J23:J25) -> 0 | ... N26: =SUM(N23:N25) -> 0 | O26: =SUM(C26:N26) -> 4703987 | Q26: Total | R26: =SUM(R23:R25) -> 7351268.6 | S26: =SUM(S23:S25) -> 5690490.4 | T26: =SUM(T23:T25) -> 16455580 | U26: =SUM(U23:U25) -> 17091575 | V26: =SUM(V23:V25) -> 11838344 | W26: =SUM(W23:W25) -> 12009859 | X26: =SUM(X23:X25) -> 0 | Y26: =SUM(Y23:Y25) -> 0 | ... AC26: =SUM(AC23:AC25) -> 0 | AE26: =SUM(R26:AC26) -> 70437118
B29: EUR | C29: 46023 | D29: 46054 | E29: 46082 | F29: 46113 | G29: 46143 | H29: 46174 | I29: 46204 | J29: 46235 | K29: 46266 | L29: 46296 | M29: 46327 | N29: 46357 | O29: TOTAL
B30: Print | C30: =SUMIF(Reunido!$BQ:$BQ,$B$30,Reunido!I:I) -> 677284.35 | D30: =SUMIF(Reunido!$BQ:$BQ,$B$30,Reunido!N:N) -> 200932.68 | E30: =SUMIF(Reunido!$BQ:$BQ,$B$30,Reunido!S:S) -> 1380174.9 | F30: =SUMIF(Reunido!$BQ:$BQ,$B$30,Reunido!X:X) -> 1571733.6 | G30: =SUMIF(Reunido!$BQ:$BQ,$B$30,Reunido!AC:AC) -> 825671.79 | H30: =SUMIF(Reunido!$BQ:$BQ,$B$30,Reunido!AH:AH) -> 1310742 | I30: =SUMIF(Reunido!$BQ:$BQ,$B$30,Reunido!AM:AM) -> 0 | J30: =SUMIF(Reunido!$BQ:$BQ,$B$30,Reunido!AR:AR) -> 0 | K30: =SUMIF(Reunido!$BQ:$BQ,$B$30,Reunido!AW:AW) -> 0 | L30: =SUMIF(Reunido!$BQ:$BQ,$B$30,Reunido!BB:BB) -> 0 | M30: =SUMIF(Reunido!$BQ:$BQ,$B$30,Reunido!BG:BG) -> 0 | N30: =SUMIF(Reunido!$BQ:$BQ,$B$30,Reunido!BL:BL) -> 0 | O30: =SUM(C30:N30) -> 5966539.3
B31: FF | C31: =SUMIF(Reunido!$BQ:$BQ,$B$31,Reunido!I:I) -> 328978.9 | D31: =SUMIF(Reunido!$BQ:$BQ,$B$31,Reunido!N:N) -> 96038.662 | E31: =SUMIF(Reunido!$BQ:$BQ,$B$31,Reunido!S:S) -> 483670.07 | F31: =SUMIF(Reunido!$BQ:$BQ,$B$31,Reunido!X:X) -> 641229.88 | G31: =SUMIF(Reunido!$BQ:$BQ,$B$31,Reunido!AC:AC) -> 174657.6 | H31: =SUMIF(Reunido!$BQ:$BQ,$B$31,Reunido!AH:AH) -> 292167.37 | I31: =SUMIF(Reunido!$BQ:$BQ,$B$31,Reunido!AM:AM) -> 0 | J31: =SUMIF(Reunido!$BQ:$BQ,$B$31,Reunido!AR:AR) -> 0 | K31: =SUMIF(Reunido!$BQ:$BQ,$B$31,Reunido!AW:AW) -> 0 | L31: =SUMIF(Reunido!$BQ:$BQ,$B$31,Reunido!BB:BB) -> 0 | M31: =SUMIF(Reunido!$BQ:$BQ,$B$31,Reunido!BG:BG) -> 0 | N31: =SUMIF(Reunido!$BQ:$BQ,$B$31,Reunido!BL:BL) -> 0 | O31: =SUM(C31:N31) -> 2016742.5
B32: IP | C32: =SUMIF(Reunido!$BQ:$BQ,$B$32,Reunido!I:I) -> 190228.06 | D32: =SUMIF(Reunido!$BQ:$BQ,$B$32,Reunido!N:N) -> 596985.73 | E32: =SUMIF(Reunido!$BQ:$BQ,$B$32,Reunido!S:S) -> 734675.18 | F32: =SUMIF(Reunido!$BQ:$BQ,$B$32,Reunido!X:X) -> 479432.74 | G32: =SUMIF(Reunido!$BQ:$BQ,$B$32,Reunido!AC:AC) -> 701045.18 | H32: =SUMIF(Reunido!$BQ:$BQ,$B$32,Reunido!AH:AH) -> 215392.85 | I32: =SUMIF(Reunido!$BQ:$BQ,$B$32,Reunido!AM:AM) -> 0 | J32: =SUMIF(Reunido!$BQ:$BQ,$B$32,Reunido!AR:AR) -> 0 | K32: =SUMIF(Reunido!$BQ:$BQ,$B$32,Reunido!AW:AW) -> 0 | L32: =SUMIF(Reunido!$BQ:$BQ,$B$32,Reunido!BB:BB) -> 0 | M32: =SUMIF(Reunido!$BQ:$BQ,$B$32,Reunido!BG:BG) -> 0 | N32: =SUMIF(Reunido!$BQ:$BQ,$B$32,Reunido!BL:BL) -> 0 | O32: =SUM(C32:N32) -> 2917759.7
B33: Total | C33: =SUM(C30:C32) -> 1196491.3 | D33: =SUM(D30:D32) -> 893957.07 | E33: =SUM(E30:E32) -> 2598520.1 | F33: =SUM(F30:F32) -> 2692396.2 | G33: =SUM(G30:G32) -> 1701374.6 | H33: =SUM(H30:H32) -> 1818302.2 | I33: =SUM(I30:I32) -> 0 | J33: =SUM(J30:J32) -> 0 | ... N33: =SUM(N30:N32) -> 0 | O33: =SUM(C33:N33) -> 10901041

Sheet Annual Sum
A3: Rótulos de Linha | B3: Soma de Kg13 | C3: Soma de R$13 | D3: Soma de EUR13
A4: CART01 / CARTIERE DI GUARCINO S.P.A. / ITA | B4: 22889 | C4: 339661.7 | D4: 57586.134
A5: HUAW01 / HANGZHOU HUAWANG NEW MATERIAL TECHNOLOGY CO. | B5: 576526 | C5: 6680439.3 | D5: 1128864
A6: KING01 / KINGDECOR (ZHEJIANG) CO., LTD | B6: 152693 | C6: 2277252.7 | D6: 386361.36
A7: KOEH02 / KOEHLER PAPER SE / DEU | B7: 362603 | C7: 4428273.1 | D7: 735586.26
A8: MALT01 / MALTA-DECOR SP. Z O. O. / POL | B8: 61316 | C8: 950499.45 | D8: 157261.01
A9: MLTV01 / VF PAPEIS S.A. / BRA | B9: 323326 | C9: 6040408.9 | D9: 1000843.7
A10: MUNK01 / MUNKSJO UNTERKOCHEN GMBH / DEU | B10: 36262 | C10: 471842.96 | D10: 81092.32
A11: MUNK04 / MUNKSJO PAPER S/A DETTINGEN / DEU | B11: 264326 | C11: 4365687.8 | D11: 729072.64
A12: MUNK07 / MUNKSJO TOLOSA S.A.U. / ESP | B12: 246629 | C12: 2710657.1 | D12: 452902.24
A13: MUNK09 / MUNKSJO CAIEIRAS LTDA / BRA | B13: 602089 | C13: 11082303 | D13: 1847292.2
A14: SUNS01 / CENTURY SUNSHINE (SHOUGUANG) SPECIALTY PAPER CO., LTD. | B14: 1683253 | C14: 19547429 | D14: 3278384.5
A15: TECH01 / Felix Schoeller GmbH & Co. / DEU | B15: 347282 | C15: 5945703.2 | D15: 983589.56
... A17: Total Geral | B17: 4703987 | C17: 65207227 | D17: 10901041

Sheet Reunido
A1: IMPRESS DECOR BRASIL - MONTHLY BASE PAPER PURCHASE 2026 | E1: JANUARY | I1: 6.2763 | J1: FEBRUARY | N1: 6.2217 | O1: MARCH | S1: 6.0461667 | T1: APRIL | X1: 5.890025 | Y1: MAY | AC1: 5.81859 | AD1: JUNE | AH1: 5.900881 | AI1: JULY | AM1: 0 | AN1: AUGUST | AR1: 0 | AS1: SEPTEMBER | AW1: 0 | AX1: OCTOBER | BB1: 0 | BC1: NOVEMBER | BG1: 0 | BH1: DECEMBER | BL1: 0 | BM1: TOTAL
E2: Quantity | F2: Price | H2: Total | J2: Quantity | K2: Price | M2: Total | O2: Quantity | P2: Price | R2: Total | T2: Quantity | U2: Price | W2: Total | Y2: Quantity | Z2: Price | AB2: Total | AD2: Quantity | AE2: Price | AG2: Total | AI2: Quantity | AJ2: Price | AL2: Total | AN2: Quantity | AO2: Price | AQ2: Total | AS2: Quantity | AT2: Price | AV2: Total | AX2: Quantity | AY2: Price | BA2: Total | BC2: Quantity | BD2: Price | BF2: Total | BH2: Quantity | BI2: Price | BK2: Total
A3: SUPPLIERS | B3: Item | C3: Paper Type | D3: Width | E3: Kg | F3: R$/kg | G3: EUR/kg | H3: R$ | I3: EUR | J3: Kg | K3: R$/kg | L3: EUR/kg | M3: R$ | N3: EUR | O3: Kg | P3: R$/kg | Q3: EUR/kg | R3: R$ | S3: EUR | T3: Kg | U3: R$/kg | V3: EUR/kg | W3: R$ | X3: EUR | Y3: Kg | Z3: R$/kg | AA3: EUR/kg | AB3: R$ | AC3: EUR | AD3: Kg | AE3: R$/kg | AF3: EUR/kg | AG3: R$ | AH3: EUR | AI3: Kg | AJ3: R$/kg | AK3: EUR/kg | AL3: R$ | AM3: EUR | AN3: Kg | AO3: R$/kg | AP3: EUR/kg | AQ3: R$ | AR3: EUR | AS3: Kg | AT3: R$/kg | AU3: EUR/kg | AV3: R$ | AW3: EUR | AX3: Kg | AY3: R$/kg | AZ3: EUR/kg | BA3: R$ | BB3: EUR | BC3: Kg | BD3: R$/kg | BE3: EUR/kg | BF3: R$ | BG3: EUR | BH3: Kg | BI3: R$/kg | BJ3: EUR/kg | BK3: R$ | BL3: EUR | BM3: Kg | BN3: R$ | BO3: EUR | BP3: Avg price / kg | BQ3: Material Group | BR3: Class
A4: CART01 / CARTIERE DI GUARCINO S.P.A. / ITA | B4: 7004664 | C4: PBM 05 0248 065 CART | D4: 2060 | E4: 0 | F4: 0 | G4: 0 | H4: 0 | I4: 0 | J4: 0 | K4: 0 | L4: 0 | M4: 0 | N4: 0 | O4: 1366 | P4: 13.55 | Q4: =P4/$S$1 -> 2.2410894 | R4: 18506.52 | S4: =R4/$S$1 -> 3060.8683 | T4: 0 | U4: 0 | V4: 0 | W4: 0 | X4: 0 | Y4: 0 | Z4: 0 | AA4: 0 | AB4: 0 | AC4: 0 | AD4: 0 | AE4: 0 | AF4: 0 | AG4: 0 | AH4: 0 | AI4: 0 | AJ4: 0 | AK4: 0 | AL4: 0 | AM4: 0 | AN4: 0 | AO4: 0 | AP4: 0 | AQ4: 0 | AR4: 0 | AS4: 0 | AT4: 0 | AU4: 0 | AV4: 0 | AW4: 0 | AX4: 0 | AY4: 0 | AZ4: 0 | BA4: 0 | BB4: 0 | BC4: 0 | BD4: 0 | BE4: 0 | BF4: 0 | BG4: 0 | BH4: 0 | BI4: 0 | BJ4: 0 | BK4: 0 | BL4: 0 | BM4: =SUM(E4,J4,O4,T4,Y4,AD4,AI4,AN4,AS4,AX4,BC4,BH4) -> 1366 | BN4: =SUM(H4,M4,R4,W4,AB4,AG4,AL4,AQ4,AV4,BA4,BF4,BK4) -> 18506.52 | BO4: =SUM(I4,N4,S4,X4,AC4,AH4,AM4,AR4,AW4,BB4,BG4,BL4) -> 3060.8683 | BP4: =IF(BM4=0,"",BO4/BM4) -> 2.2407528 | BQ4: Print
A5: CART01 / CARTIERE DI GUARCINO S.P.A. / ITA | B5: 7002369 | C5: DPU 01 0002 80 CART | D5: 1865 | E5: 0 | F5: 0 | G5: 0 | H5: 0 | I5: 0 | J5: 0 | K5: 0 | L5: 0 | M5: 0 | N5: 0 | O5: 0 | P5: 0 | Q5: 0 | R5: 0 | S5: 0 | T5: 7391 | U5: 16.98 | V5: =U5/$X$1 -> 2.8828401 | W5: 125470.72 | X5: =W5/$X$1 -> 21302.239 | Y5: 0 | Z5: 0 | AA5: 0 | AB5: 0 | AC5: 0 | AD5: 0 | AE5: 0 | AF5: 0 | AG5: 0 | AH5: 0 | AI5: 0 | AJ5: 0 | AK5: 0 | AL5: 0 | AM5: 0 | AN5: 0 | AO5: 0 | AP5: 0 | AQ5: 0 | AR5: 0 | AS5: 0 | AT5: 0 | AU5: 0 | AV5: 0 | AW5: 0 | AX5: 0 | AY5: 0 | AZ5: 0 | BA5: 0 | BB5: 0 | BC5: 0 | BD5: 0 | BE5: 0 | BF5: 0 | BG5: 0 | BH5: 0 | BI5: 0 | BJ5: 0 | BK5: 0 | BL5: 0 | BM5: =SUM(E5,J5,O5,T5,Y5,AD5,AI5,AN5,AS5,AX5,BC5,BH5) -> 7391 | BN5: =SUM(H5,M5,R5,W5,AB5,AG5,AL5,AQ5,AV5,BA5,BF5,BK5) -> 125470.72 | BO5: =SUM(I5,N5,S5,X5,AC5,AH5,AM5,AR5,AW5,BB5,BG5,BL5) -> 21302.239 | BP5: =IF(BM5=0,"",BO5/BM5) -> 2.8821863 | BQ5: IP | BR5: white
A6: CART01 / CARTIERE DI GUARCINO S.P.A. / ITA | B6: 7004755 | C6: PBM 05 0483 068 CART | D6: 1870 | E6: 0 | F6: 0 | G6: 0 | H6: 0 | I6: 0 | J6: 0 | K6: 0 | L6: 0 | M6: 0 | N6: 0 | O6: 0 | P6: 0 | Q6: 0 | R6: 0 | S6: 0 | T6: 7695 | U6: 13.85 | V6: =U6/$X$1 -> 2.3514331 | W6: 106551.93 | X6: =W6/$X$1 -> 18090.234 | Y6: 0 | Z6: 0 | AA6: 0 | AB6: 0 | AC6: 0 | AD6: 0 | AE6: 0 | AF6: 0 | AG6: 0 | AH6: 0 | AI6: 0 | AJ6: 0 | AK6: 0 | AL6: 0 | AM6: 0 | AN6: 0 | AO6: 0 | AP6: 0 | AQ6: 0 | AR6: 0 | AS6: 0 | AT6: 0 | AU6: 0 | AV6: 0 | AW6: 0 | AX6: 0 | AY6: 0 | AZ6: 0 | BA6: 0 | BB6: 0 | BC6: 0 | BD6: 0 | BE6: 0 | BF6: 0 | BG6: 0 | BH6: 0 | BI6: 0 | BJ6: 0 | BK6: 0 | BL6: 0 | BM6: =SUM(E6,J6,O6,T6,Y6,AD6,AI6,AN6,AS6,AX6,BC6,BH6) -> 7695 | BN6: =SUM(H6,M6,R6,W6,AB6,AG6,AL6,AQ6,AV6,BA6,BF6,BK6) -> 106551.93 | BO6: =SUM(I6,N6,S6,X6,AC6,AH6,AM6,AR6,AW6,BB6,BG6,BL6) -> 18090.234 | BP6: =IF(BM6=0,"",BO6/BM6) -> 2.3509076 | BQ6: Print
A7: CART01 / CARTIERE DI GUARCINO S.P.A. / ITA | B7: 7004756 | C7: PBM 05 689 068 CART | D7: 1870 | E7: 0 | F7: 0 | G7: 0 | H7: 0 | I7: 0 | J7: 0 | K7: 0 | L7: 0 | M7: 0 | N7: 0 | O7: 0 | P7: 0 | Q7: 0 | R7: 0 | S7: 0 | T7: 6437 | U7: 13.85 | V7: =U7/$X$1 -> 2.3514331 | W7: 89132.53 | X7: =W7/$X$1 -> 15132.793 | Y7: 0 | Z7: 0 | AA7: 0 | AB7: 0 | AC7: 0 | AD7: 0 | AE7: 0 | AF7: 0 | AG7: 0 | AH7: 0 | AI7: 0 | AJ7: 0 | AK7: 0 | AL7: 0 | AM7: 0 | AN7: 0 | AO7: 0 | AP7: 0 | AQ7: 0 | AR7: 0 | AS7: 0 | AT7: 0 | AU7: 0 | AV7: 0 | AW7: 0 | AX7: 0 | AY7: 0 | AZ7: 0 | BA7: 0 | BB7: 0 | BC7: 0 | BD7: 0 | BE7: 0 | BF7: 0 | BG7: 0 | BH7: 0 | BI7: 0 | BJ7: 0 | BK7: 0 | BL7: 0 | BM7: =SUM(E7,J7,O7,T7,Y7,AD7,AI7,AN7,AS7,AX7,BC7,BH7) -> 6437 | BN7: =SUM(H7,M7,R7,W7,AB7,AG7,AL7,AQ7,AV7,BA7,BF7,BK7) -> 89132.53 | BO7: =SUM(I7,N7,S7,X7,AC7,AH7,AM7,AR7,AW7,BB7,BG7,BL7) -> 15132.793 | BP7: =IF(BM7=0,"",BO7/BM7) -> 2.3509077 | BQ7: Print
A8: HUAW01 / HANGZHOU HUAWANG NEW MATERIAL TECHNOLOGY CO. | B8: 18.856 | C8: HUAWON GRAY HG5089 (689) 68G/M2 1870MM (FSC MC) | D8: 1870 | E8: 25137 | F8: 13.70296 | G8: 2.1832925 | H8: 344451.31 | I8: 54881.423 | J8: 25228 | K8: 13.602142 | L8: 2.2111993 | M8: 343154.84 | N8: 55784.135 | O8: 0 | P8: 0 | Q8: 0 | R8: 0 | S8: 0 | T8: 0 | U8: 0 | V8: 0 | W8: 0 | X8: 0 | Y8: 0 | Z8: 0 | AA8: 0 | AB8: 0 | AC8: 0 | AD8: 0 | AE8: 0 | AF8: 0 | AG8: 0 | AH8: 0 | AI8: 0 | AJ8: 0 | AK8: 0 | AL8: 0 | AM8: 0 | AN8: 0 | AO8: 0 | AP8: 0 | AQ8: 0 | AR8: 0 | AS8: 0 | AT8: 0 | AU8: 0 | AV8: 0 | AW8: 0 | AX8: 0 | AY8: 0 | AZ8: 0 | BA8: 0 | BB8: 0 | BC8: 0 | BD8: 0 | BE8: 0 | BF8: 0 | BG8: 0 | BH8: 0 | BI8: 0 | BJ8: 0 | BK8: 0 | BL8: 0 | BM8: =SUM(E8,J8,O8,T8,Y8,AD8,AI8,AN8,AS8,AX8,BC8,BH8) -> 50365 | BN8: =SUM(H8,M8,R8,W8,AB8,AG8,AL8,AQ8,AV8,BA8,BF8,BK8) -> 687606.14 | BO8: =SUM(I8,N8,S8,X8,AC8,AH8,AM8,AR8,AW8,BB8,BG8,BL8) -> 110665.56 | BP8: =IF(BM8=0,"",BO8/BM8) -> 2.1972711 | BQ8: Print
A9: HUAW01 / HANGZHOU HUAWANG NEW MATERIAL TECHNOLOGY CO. | B9: 7002028 | C9: PBM 01 1833 070 HUAW | D9: 1860 | E9: 0 | F9: 0 | G9: 0 | H9: 0 | I9: 0 | J9: 0 | K9: 0 | L9: 0 | M9: 0 | N9: 0 | O9: 2030 | P9: 9.44 | Q9: =P9/$S$1 -> 1.5613198 | R9: 19153.44 | S9: =R9/$S$1 -> 3167.865 | T9: 0 | U9: 0 | V9: 0 | W9: 0 | X9: 0 | Y9: 0 | Z9: 0 | AA9: 0 | AB9: 0 | AC9: 0 | AD9: 0 | AE9: 0 | AF9: 0 | AG9: 0 | AH9: 0 | AI9: 0 | AJ9: 0 | AK9: 0 | AL9: 0 | AM9: 0 | AN9: 0 | AO9: 0 | AP9: 0 | AQ9: 0 | AR9: 0 | AS9: 0 | AT9: 0 | AU9: 0 | AV9: 0 | AW9: 0 | AX9: 0 | AY9: 0 | AZ9: 0 | BA9: 0 | BB9: 0 | BC9: 0 | BD9: 0 | BE9: 0 | BF9: 0 | BG9: 0 | BH9: 0 | BI9: 0 | BJ9: 0 | BK9: 0 | BL9: 0 | BM9: =SUM(E9,J9,O9,T9,Y9,AD9,AI9,AN9,AS9,AX9,BC9,BH9) -> 2030 | BN9: =SUM(H9,M9,R9,W9,AB9,AG9,AL9,AQ9,AV9,BA9,BF9,BK9) -> 19153.44 | BO9: =SUM(I9,N9,S9,X9,AC9,AH9,AM9,AR9,AW9,BB9,BG9,BL9) -> 3167.865 | BP9: =IF(BM9=0,"",BO9/BM9) -> 1.5605246 | BQ9: Print
A10: HUAW01 / HANGZHOU HUAWANG NEW MATERIAL TECHNOLOGY CO. | B10: 2010899 | C10: PBM 05 0483 068 HUAW (5083) | D10: 1870 | E10: 0 | F10: 0 | G10: 0 | H10: 0 | I10: 0 | J10: 0 | K10: 0 | L10: 0 | M10: 0 | N10: 0 | O10: 0 | P10: 0 | Q10: 0 | R10: 0 | S10: 0 | T10: 190866 | U10: 11.406667 | V10: =U10/$X$1 -> 1.9366075 | W10: 2168071.2 | X10: =W10/$X$1 -> 368092.02 | Y10: 49815 | Z10: 11.4 | AA10: =Z10/$AC$1 -> 1.9592375 | AB10: 567892.49 | AC10: =AB10/$AC$1 -> 97599.674 | AD10: 49515 | AE10: 11.504796 | AF10: =AE10/$AH$1 -> 1.9496743 | AG10: 569659.97 | AH10: =AG10/$AH$1 -> 96538.123 | AI10: 0 | AJ10: 0 | AK10: 0 | AL10: 0 | AM10: 0 | AN10: 0 | AO10: 0 | AP10: 0 | AQ10: 0 | AR10: 0 | AS10: 0 | AT10: 0 | AU10: 0 | AV10: 0 | AW10: 0 | AX10: 0 | AY10: 0 | AZ10: 0 | BA10: 0 | BB10: 0 | BC10: 0 | BD10: 0 | BE10: 0 | BF10: 0 | BG10: 0 | BH10: 0 | BI10: 0 | BJ10: 0 | BK10: 0 | BL10: 0 | BM10: =SUM(E10,J10,O10,T10,Y10,AD10,AI10,AN10,AS10,AX10,BC10,BH10) -> 290196 | BN10: =SUM(H10,M10,R10,W10,AB10,AG10,AL10,AQ10,AV10,BA10,BF10,BK10) -> 3305623.7 | BO10: =SUM(I10,N10,S10,X10,AC10,AH10,AM10,AR10,AW10,BB10,BG10,BL10) -> 562229.82 | BP10: =IF(BM10=0,"",BO10/BM10) -> 1.9374141 | BQ10: Print
A11: HUAW01 / HANGZHOU HUAWANG NEW MATERIAL TECHNOLOGY CO. | B11: 2090448 | C11: PBM 05 689 068 HUAW (5089) | D11: 1870 | E11: 0 | F11: 0 | G11: 0 | H11: 0 | I11: 0 | J11: 0 | K11: 0 | L11: 0 | M11: 0 | N11: 0 | O11: 0 | P11: 0 | Q11: 0 | R11: 0 | S11: 0 | T11: 75156 | U11: 11.32 | V11: =U11/$X$1 -> 1.9218934 | W11: 847291.6 | X11: =W11/$X$1 -> 143851.95 | Y11: 0 | Z11: 0 | AA11: 0 | AB11: 0 | AC11: 0 | AD11: 49727 | AE11: 11.46166 | AF11: =AE11/$AH$1 -> 1.9423642 | AG11: 569953.96 | AH11: =AG11/$AH$1 -> 96587.944 | AI11: 0 | AJ11: 0 | AK11: 0 | AL11: 0 | AM11: 0 | AN11: 0 | AO11: 0 | AP11: 0 | AQ11: 0 | AR11: 0 | AS11: 0 | AT11: 0 | AU11: 0 | AV11: 0 | AW11: 0 | AX11: 0 | AY11: 0 | AZ11: 0 | BA11: 0 | BB11: 0 | BC11: 0 | BD11: 0 | BE11: 0 | BF11: 0 | BG11: 0 | BH11: 0 | BI11: 0 | BJ11: 0 | BK11: 0 | BL11: 0 | BM11: =SUM(E11,J11,O11,T11,Y11,AD11,AI11,AN11,AS11,AX11,BC11,BH11) -> 124883 | BN11: =SUM(H11,M11,R11,W11,AB11,AG11,AL11,AQ11,AV11,BA11,BF11,BK11) -> 1417245.6 | BO11: =SUM(I11,N11,S11,X11,AC11,AH11,AM11,AR11,AW11,BB11,BG11,BL11) -> 240439.9 | BP11: =IF(BM11=0,"",BO11/BM11) -> 1.9253213 | BQ11: Print
A12: HUAW01 / HANGZHOU HUAWANG NEW MATERIAL TECHNOLOGY CO. | B12: 7002372 | C12: PBM 05 0248 065 HUAW | D12: 1870 | E12: 0 | F12: 0 | G12: 0 | H12: 0 | I12: 0 | J12: 0 | K12: 0 | L12: 0 | M12: 0 | N12: 0 | O12: 0 | P12: 0 | Q12: 0 | R12: 0 | S12: 0 | T12: 100046 | U12: 11.553333 | V12: =U12/$X$1 -> 1.9615084 | W12: 1152059.7 | X12: =W12/$X$1 -> 195595.05 | Y12: 0 | Z12: 0 | AA12: 0 | AB12: 0 | AC12: 0 | AD12: 0 | AE12: 0 | AF12: 0 | AG12: 0 | AH12: 0 | AI12: 0 | AJ12: 0 | AK12: 0 | AL12: 0 | AM12: 0 | AN12: 0 | AO12: 0 | AP12: 0 | AQ12: 0 | AR12: 0 | AS12: 0 | AT12: 0 | AU12: 0 | AV12: 0 | AW12: 0 | AX12: 0 | AY12: 0 | AZ12: 0 | BA12: 0 | BB12: 0 | BC12: 0 | BD12: 0 | BE12: 0 | BF12: 0 | BG12: 0 | BH12: 0 | BI12: 0 | BJ12: 0 | BK12: 0 | BL12: 0 | BM12: =SUM(E12,J12,O12,T12,Y12,AD12,AI12,AN12,AS12,AX12,BC12,BH12) -> 100046 | BN12: =SUM(H12,M12,R12,W12,AB12,AG12,AL12,AQ12,AV12,BA12,BF12,BK12) -> 1152059.7 | BO12: =SUM(I12,N12,S12,X12,AC12,AH12,AM12,AR12,AW12,BB12,BG12,BL12) -> 195595.05 | BP12: =IF(BM12=0,"",BO12/BM12) -> 1.9550512 | BQ12: Print
A13: HUAW01 / HANGZHOU HUAWANG NEW MATERIAL TECHNOLOGY CO. | B13: 7004758 | C13: PBM 01 0004 070 HUAW | D13: 1870 | E13: 0 | F13: 0 | G13: 0 | H13: 0 | I13: 0 | J13: 0 | K13: 0 | L13: 0 | M13: 0 | N13: 0 | O13: 0 | P13: 0 | Q13: 0 | R13: 0 | S13: 0 | T13: 5928 | U13: 10.97 | V13: =U13/$X$1 -> 1.8624709 | W13: 65000.52 | X13: =W13/$X$1 -> 11035.695 | Y13: 0 | Z13: 0 | AA13: 0 | AB13: 0 | AC13: 0 | AD13: 0 | AE13: 0 | AF13: 0 | AG13: 0 | AH13: 0 | AI13: 0 | AJ13: 0 | AK13: 0 | AL13: 0 | AM13: 0 | AN13: 0 | AO13: 0 | AP13: 0 | AQ13: 0 | AR13: 0 | AS13: 0 | AT13: 0 | AU13: 0 | AV13: 0 | AW13: 0 | AX13: 0 | AY13: 0 | AZ13: 0 | BA13: 0 | BB13: 0 | BC13: 0 | BD13: 0 | BE13: 0 | BF13: 0 | BG13: 0 | BH13: 0 | BI13: 0 | BJ13: 0 | BK13: 0 | BL13: 0 | BM13: =SUM(E13,J13,O13,T13,Y13,AD13,AI13,AN13,AS13,AX13,BC13,BH13) -> 5928 | BN13: =SUM(H13,M13,R13,W13,AB13,AG13,AL13,AQ13,AV13,BA13,BF13,BK13) -> 65000.52 | BO13: =SUM(I13,N13,S13,X13,AC13,AH13,AM13,AR13,AW13,BB13,BG13,BL13) -> 11035.695 | BP13: =IF(BM13=0,"",BO13/BM13) -> 1.861622 | BQ13: Print
A14: HUAW01 / HANGZHOU HUAWANG NEW MATERIAL TECHNOLOGY CO. | B14: 7004759 | C14: DPU 01 0104 080 HUAW | D14: 1860 | E14: 0 | F14: 0 | G14: 0 | H14: 0 | I14: 0 | J14: 0 | K14: 0 | L14: 0 | M14: 0 | N14: 0 | O14: 0 | P14: 0 | Q14: 0 | R14: 0 | S14: 0 | T14: 3078 | U14: 10.97 | V14: =U14/$X$1 -> 1.8624709 | W14: 33750.27 | X14: =W14/$X$1 -> 5730.0725 | Y14: 0 | Z14: 0 | AA14: 0 | AB14: 0 | AC14: 0 | AD14: 0 | AE14: 0 | AF14: 0 | AG14: 0 | AH14: 0 | AI14: 0 | AJ14: 0 | AK14: 0 | AL14: 0 | AM14: 0 | AN14: 0 | AO14: 0 | AP14: 0 | AQ14: 0 | AR14: 0 | AS14: 0 | AT14: 0 | AU14: 0 | AV14: 0 | AW14: 0 | AX14: 0 | AY14: 0 | AZ14: 0 | BA14: 0 | BB14: 0 | BC14: 0 | BD14: 0 | BE14: 0 | BF14: 0 | BG14: 0 | BH14: 0 | BI14: 0 | BJ14: 0 | BK14: 0 | BL14: 0 | BM14: =SUM(E14,J14,O14,T14,Y14,AD14,AI14,AN14,AS14,AX14,BC14,BH14) -> 3078 | BN14: =SUM(H14,M14,R14,W14,AB14,AG14,AL14,AQ14,AV14,BA14,BF14,BK14) -> 33750.27 | BO14: =SUM(I14,N14,S14,X14,AC14,AH14,AM14,AR14,AW14,BB14,BG14,BL14) -> 5730.0725 | BP14: =IF(BM14=0,"",BO14/BM14) -> 1.861622 | BQ14: Print
A15: KING01 / KINGDECOR (ZHEJIANG) CO., LTD | B15: 7002362 | C15: PIP 01 9370 070 KING PO NEW WHITE | D15: 1880 | E15: 0 | F15: 0 | G15: 0 | H15: 0 | I15: 0 | J15: 0 | K15: 0 | L15: 0 | M15: 0 | N15: 0 | O15: 0 | P15: 0 | Q15: 0 | R15: 0 | S15: 0 | T15: 45773 | U15: 16.7 | V15: =U15/$X$1 -> 2.8353021 | W15: 764559.24 | X15: =W15/$X$1 -> 129805.77 | Y15: 0 | Z15: 0 | AA15: 0 | AB15: 0 | AC15: 0 | AD15: 50485 | AE15: 16.95 | AF15: 2.8724525 | AG15: 855926.73 | AH15: 145050.67 | AI15: 0 | AJ15: 0 | AK15: 0 | AL15: 0 | AM15: 0 | AN15: 0 | AO15: 0 | AP15: 0 | AQ15: 0 | AR15: 0 | AS15: 0 | AT15: 0 | AU15: 0 | AV15: 0 | AW15: 0 | AX15: 0 | AY15: 0 | AZ15: 0 | BA15: 0 | BB15: 0 | BC15: 0 | BD15: 0 | BE15: 0 | BF15: 0 | BG15: 0 | BH15: 0 | BI15: 0 | BJ15: 0 | BK15: 0 | BL15: 0 | BM15: =SUM(E15,J15,O15,T15,Y15,AD15,AI15,AN15,AS15,AX15,BC15,BH15) -> 96258 | BN15: =SUM(H15,M15,R15,W15,AB15,AG15,AL15,AQ15,AV15,BA15,BF15,BK15) -> 1620486 | BO15: =SUM(I15,N15,S15,X15,AC15,AH15,AM15,AR15,AW15,BB15,BG15,BL15) -> 274856.44 | BP15: =IF(BM15=0,"",BO15/BM15) -> 2.855414 | BQ15: FF
A16: KING01 / KINGDECOR (ZHEJIANG) CO., LTD | B16: 7004722 | C16: PBM 01 0087 050 KING (XH1007D) | D16: 1870 | E16: 0 | F16: 0 | G16: 0 | H16: 0 | I16: 0 | J16: 0 | K16: 0 | L16: 0 | M16: 0 | N16: 0 | O16: 0 | P16: 0 | Q16: 0 | R16: 0 | S16: 0 | T16: 841 | U16: 7.18 | V16: =U16/$X$1 -> 1.2190101 | W16: 6037.94 | X16: =W16/$X$1 -> 1025.1128 | Y16: 0 | Z16: 0 | AA16: 0 | AB16: 0 | AC16: 0 | AD16: 0 | AE16: 0 | AF16: 0 | AG16: 0 | AH16: 0 | AI16: 0 | AJ16: 0 | AK16: 0 | AL16: 0 | AM16: 0 | AN16: 0 | AO16: 0 | AP16: 0 | AQ16: 0 | AR16: 0 | AS16: 0 | AT16: 0 | AU16: 0 | AV16: 0 | AW16: 0 | AX16: 0 | AY16: 0 | AZ16: 0 | BA16: 0 | BB16: 0 | BC16: 0 | BD16: 0 | BE16: 0 | BF16: 0 | BG16: 0 | BH16: 0 | BI16: 0 | BJ16: 0 | BK16: 0 | BL16: 0 | BM16: =SUM(E16,J16,O16,T16,Y16,AD16,AI16,AN16,AS16,AX16,BC16,BH16) -> 841 | BN16: =SUM(H16,M16,R16,W16,AB16,AG16,AL16,AQ16,AV16,BA16,BF16,BK16) -> 6037.94 | BO16: =SUM(I16,N16,S16,X16,AC16,AH16,AM16,AR16,AW16,BB16,BG16,BL16) -> 1025.1128 | BP16: =IF(BM16=0,"",BO16/BM16) -> 1.2189213 | BQ16: Print
A17: KING01 / KINGDECOR (ZHEJIANG) CO., LTD | B17: 7004757 | C17: PIP 01 9370 065 KING PO NEW WHITE | D17: 1880 | E17: 0 | F17: 0 | G17: 0 | H17: 0 | I17: 0 | J17: 0 | K17: 0 | L17: 0 | M17: 0 | N17: 0 | O17: 0 | P17: 0 | Q17: 0 | R17: 0 | S17: 0 | T17: 5021 | U17: 16.7 | V17: =U17/$X$1 -> 2.8353021 | W17: 83867.17 | X17: =W17/$X$1 -> 14238.848 | Y17: 0 | Z17: 0 | AA17: 0 | AB17: 0 | AC17: 0 | AD17: 0 | AE17: 0 | AF17: 0 | AG17: 0 | AH17: 0 | AI17: 0 | AJ17: 0 | AK17: 0 | AL17: 0 | AM17: 0 | AN17: 0 | AO17: 0 | AP17: 0 | AQ17: 0 | AR17: 0 | AS17: 0 | AT17: 0 | AU17: 0 | AV17: 0 | AW17: 0 | AX17: 0 | AY17: 0 | AZ17: 0 | BA17: 0 | BB17: 0 | BC17: 0 | BD17: 0 | BE17: 0 | BF17: 0 | BG17: 0 | BH17: 0 | BI17: 0 | BJ17: 0 | BK17: 0 | BL17: 0 | BM17: =SUM(E17,J17,O17,T17,Y17,AD17,AI17,AN17,AS17,AX17,BC17,BH17) -> 5021 | BN17: =SUM(H17,M17,R17,W17,AB17,AG17,AL17,AQ17,AV17,BA17,BF17,BK17) -> 83867.17 | BO17: =SUM(I17,N17,S17,X17,AC17,AH17,AM17,AR17,AW17,BB17,BG17,BL17) -> 14238.848 | BP17: =IF(BM17=0,"",BO17/BM17) -> 2.835859 | BQ17: FF
A18: KING01 / KINGDECOR (ZHEJIANG) CO., LTD | B18: 7004848 | C18: DPU 01 0104 070 KING | D18: 1870 | E18: 0 | F18: 0 | G18: 0 | H18: 0 | I18: 0 | J18: 0 | K18: 0 | L18: 0 | M18: 0 | N18: 0 | O18: 0 | P18: 0 | Q18: 0 | R18: 0 | S18: 0 | T18: 50573 | U18: 11.21 | V18: =U18/$X$1 -> 1.9032177 | W18: 566861.63 | X18: =W18/$X$1 -> 96240.955 | Y18: 0 | Z18: 0 | AA18: 0 | AB18: 0 | AC18: 0 | AD18: 0 | AE18: 0 | AF18: 0 | AG18: 0 | AH18: 0 | AI18: 0 | AJ18: 0 | AK18: 0 | AL18: 0 | AM18: 0 | AN18: 0 | AO18: 0 | AP18: 0 | AQ18: 0 | AR18: 0 | AS18: 0 | AT18: 0 | AU18: 0 | AV18: 0 | AW18: 0 | AX18: 0 | AY18: 0 | AZ18: 0 | BA18: 0 | BB18: 0 | BC18: 0 | BD18: 0 | BE18: 0 | BF18: 0 | BG18: 0 | BH18: 0 | BI18: 0 | BJ18: 0 | BK18: 0 | BL18: 0 | BM18: =SUM(E18,J18,O18,T18,Y18,AD18,AI18,AN18,AS18,AX18,BC18,BH18) -> 50573 | BN18: =SUM(H18,M18,R18,W18,AB18,AG18,AL18,AQ18,AV18,BA18,BF18,BK18) -> 566861.63 | BO18: =SUM(I18,N18,S18,X18,AC18,AH18,AM18,AR18,AW18,BB18,BG18,BL18) -> 96240.955 | BP18: =IF(BM18=0,"",BO18/BM18) -> 1.9030106 | BQ18: Print
A19: KOEH02 / KOEHLER PAPER SE / DEU | B19: 14.108 | C19: KOEHLER 8269 ECO 68G/M2 1870MM (FSC MC) | D19: 1870 | E19: 51051 | F19: 14.509955 | G19: 2.311871 | H19: 740747.71 | I19: 118023.33 | J19: 0 | K19: 0 | L19: 0 | M19: 0 | N19: 0 | O19: 0 | P19: 0 | Q19: 0 | R19: 0 | S19: 0 | T19: 0 | U19: 0 | V19: 0 | W19: 0 | X19: 0 | Y19: 0 | Z19: 0 | AA19: 0 | AB19: 0 | AC19: 0 | AD19: 0 | AE19: 0 | AF19: 0 | AG19: 0 | AH19: 0 | AI19: 0 | AJ19: 0 | AK19: 0 | AL19: 0 | AM19: 0 | AN19: 0 | AO19: 0 | AP19: 0 | AQ19: 0 | AR19: 0 | AS19: 0 | AT19: 0 | AU19: 0 | AV19: 0 | AW19: 0 | AX19: 0 | AY19: 0 | AZ19: 0 | BA19: 0 | BB19: 0 | BC19: 0 | BD19: 0 | BE19: 0 | BF19: 0 | BG19: 0 | BH19: 0 | BI19: 0 | BJ19: 0 | BK19: 0 | BL19: 0 | BM19: =SUM(E19,J19,O19,T19,Y19,AD19,AI19,AN19,AS19,AX19,BC19,BH19) -> 51051 | BN19: =SUM(H19,M19,R19,W19,AB19,AG19,AL19,AQ19,AV19,BA19,BF19,BK19) -> 740747.71 | BO19: =SUM(I19,N19,S19,X19,AC19,AH19,AM19,AR19,AW19,BB19,BG19,BL19) -> 118023.33 | BP19: =IF(BM19=0,"",BO19/BM19) -> 2.311871 | BQ19: Print
A20: KOEH02 / KOEHLER PAPER SE / DEU | B20: 14.127 | C20: KOEHLER 8292 ECO 70G/M² 1870MM LOP (FSC MC) | D20: 1870 | E20: 24960 | F20: 12.399134 | G20: 1.9755539 | H20: 309482.38 | I20: 49309.825 | J20: 0 | K20: 0 | L20: 0 | M20: 0 | N20: 0 | O20: 0 | P20: 0 | Q20: 0 | R20: 0 | S20: 0 | T20: 0 | U20: 0 | V20: 0 | W20: 0 | X20: 0 | Y20: 0 | Z20: 0 | AA20: 0 | AB20: 0 | AC20: 0 | AD20: 0 | AE20: 0 | AF20: 0 | AG20: 0 | AH20: 0 | AI20: 0 | AJ20: 0 | AK20: 0 | AL20: 0 | AM20: 0 | AN20: 0 | AO20: 0 | AP20: 0 | AQ20: 0 | AR20: 0 | AS20: 0 | AT20: 0 | AU20: 0 | AV20: 0 | AW20: 0 | AX20: 0 | AY20: 0 | AZ20: 0 | BA20: 0 | BB20: 0 | BC20: 0 | BD20: 0 | BE20: 0 | BF20: 0 | BG20: 0 | BH20: 0 | BI20: 0 | BJ20: 0 | BK20: 0 | BL20: 0 | BM20: =SUM(E20,J20,O20,T20,Y20,AD20,AI20,AN20,AS20,AX20,BC20,BH20) -> 24960 | BN20: =SUM(H20,M20,R20,W20,AB20,AG20,AL20,AQ20,AV20,BA20,BF20,BK20) -> 309482.38 | BO20: =SUM(I20,N20,S20,X20,AC20,AH20,AM20,AR20,AW20,BB20,BG20,BL20) -> 49309.825 | BP20: =IF(BM20=0,"",BO20/BM20) -> 1.9755539 | BQ20: Print
A21: KOEH02 / KOEHLER PAPER SE / DEU | B21: 7004665 | C21: PBM 05 0248 065 KOEH | D21: 2060 | E21: 0 | F21: 0 | G21: 0 | H21: 0 | I21: 0 | J21: 0 | K21: 0 | L21: 0 | M21: 0 | N21: 0 | O21: 2296 | P21: 13.91 | Q21: =P21/$S$1 -> 2.3006313 | R21: 31939.33 | S21: =R21/$S$1 -> 5282.5752 | T21: 0 | U21: 0 | V21: 0 | W21: 0 | X21: 0 | Y21: 0 | Z21: 0 | AA21: 0 | AB21: 0 | AC21: 0 | AD21: 0 | AE21: 0 | AF21: 0 | AG21: 0 | AH21: 0 | AI21: 0 | AJ21: 0 | AK21: 0 | AL21: 0 | AM21: 0 | AN21: 0 | AO21: 0 | AP21: 0 | AQ21: 0 | AR21: 0 | AS21: 0 | AT21: 0 | AU21: 0 | AV21: 0 | AW21: 0 | AX21: 0 | AY21: 0 | AZ21: 0 | BA21: 0 | BB21: 0 | BC21: 0 | BD21: 0 | BE21: 0 | BF21: 0 | BG21: 0 | BH21: 0 | BI21: 0 | BJ21: 0 | BK21: 0 | BL21: 0 | BM21: =SUM(E21,J21,O21,T21,Y21,AD21,AI21,AN21,AS21,AX21,BC21,BH21) -> 2296 | BN21: =SUM(H21,M21,R21,W21,AB21,AG21,AL21,AQ21,AV21,BA21,BF21,BK21) -> 31939.33 | BO21: =SUM(I21,N21,S21,X21,AC21,AH21,AM21,AR21,AW21,BB21,BG21,BL21) -> 5282.5752 | BP21: =IF(BM21=0,"",BO21/BM21) -> 2.3007732 | BQ21: Print
A22: KOEH02 / KOEHLER PAPER SE / DEU | B22: 2032265 | C22: PBM 02 8269 068 KOEH | D22: 1870 | E22: 0 | F22: 0 | G22: 0 | H22: 0 | I22: 0 | J22: 0 | K22: 0 | L22: 0 | M22: 0 | N22: 0 | O22: 99116 | P22: 12.405 | Q22: =P22/$S$1 -> 2.0517132 | R22: 1229688.1 | S22: =R22/$S$1 -> 203383.1 | T22: 0 | U22: 0 | V22: 0 | W22: 0 | X22: 0 | Y22: 50006 | Z22: 11.93 | AA22: =Z22/$AC$1 -> 2.0503249 | AB22: 596565.18 | AC22: =AB22/$AC$1 -> 102527.45 | AD22: 49574 | AE22: 12.094878 | AF22: =AE22/$AH$1 -> 2.0496733 | AG22: 599591.48 | AH22: =AG22/$AH$1 -> 101610.5 | AI22: 0 | AJ22: 0 | AK22: 0 | AL22: 0 | AM22: 0 | AN22: 0 | AO22: 0 | AP22: 0 | AQ22: 0 | AR22: 0 | AS22: 0 | AT22: 0 | AU22: 0 | AV22: 0 | AW22: 0 | AX22: 0 | AY22: 0 | AZ22: 0 | BA22: 0 | BB22: 0 | BC22: 0 | BD22: 0 | BE22: 0 | BF22: 0 | BG22: 0 | BH22: 0 | BI22: 0 | BJ22: 0 | BK22: 0 | BL22: 0 | BM22: =SUM(E22,J22,O22,T22,Y22,AD22,AI22,AN22,AS22,AX22,BC22,BH22) -> 198696 | BN22: =SUM(H22,M22,R22,W22,AB22,AG22,AL22,AQ22,AV22,BA22,BF22,BK22) -> 2425844.8 | BO22: =SUM(I22,N22,S22,X22,AC22,AH22,AM22,AR22,AW22,BB22,BG22,BL22) -> 407521.05 | BP22: =IF(BM22=0,"",BO22/BM22) -> 2.0509776 | BQ22: Print
A23: KOEH02 / KOEHLER PAPER SE / DEU | B23: 7000451 | C23: PBM 02 8292 070 KOEH LOP | D23: 1870 | E23: 0 | F23: 0 | G23: 0 | H23: 0 | I23: 0 | J23: 0 | K23: 0 | L23: 0 | M23: 0 | N23: 0 | O23: 25900 | P23: 10.4 | Q23: =P23/$S$1 -> 1.7200981 | R23: 269435.21 | S23: =R23/$S$1 -> 44562.981 | T23: 0 | U23: 0 | V23: 0 | W23: 0 | X23: 0 | Y23: 24590 | Z23: 10.08 | AA23: =Z23/$AC$1 -> 1.7323785 | AB23: 247785.76 | AC23: =AB23/$AC$1 -> 42585.19 | AD23: 0 | AE23: 0 | AF23: 0 | AG23: 0 | AH23: 0 | AI23: 0 | AJ23: 0 | AK23: 0 | AL23: 0 | AM23: 0 | AN23: 0 | AO23: 0 | AP23: 0 | AQ23: 0 | AR23: 0 | AS23: 0 | AT23: 0 | AU23: 0 | AV23: 0 | AW23: 0 | AX23: 0 | AY23: 0 | AZ23: 0 | BA23: 0 | BB23: 0 | BC23: 0 | BD23: 0 | BE23: 0 | BF23: 0 | BG23: 0 | BH23: 0 | BI23: 0 | BJ23: 0 | BK23: 0 | BL23: 0 | BM23: =SUM(E23,J23,O23,T23,Y23,AD23,AI23,AN23,AS23,AX23,BC23,BH23) -> 50490 | BN23: =SUM(H23,M23,R23,W23,AB23,AG23,AL23,AQ23,AV23,BA23,BF23,BK23) -> 517220.97 | BO23: =SUM(I23,N23,S23,X23,AC23,AH23,AM23,AR23,AW23,BB23,BG23,BL23) -> 87148.171 | BP23: =IF(BM23=0,"",BO23/BM23) -> 1.7260481 | BQ23: Print
A24: KOEH02 / KOEHLER PAPER SE / DEU | B24: 7000451 | C24: PBM 02 8292 070 KOEH LOP | D24: 2175 | E24: 0 | F24: 0 | G24: 0 | H24: 0 | I24: 0 | J24: 0 | K24: 0 | L24: 0 | M24: 0 | N24: 0 | O24: 0 | P24: 0 | Q24: 0 | R24: 0 | S24: 0 | T24: 0 | U24: 0 | V24: 0 | W24: 0 | X24: 0 | Y24: 0 | Z24: 0 | AA24: 0 | AB24: 0 | AC24: 0 | AD24: 10143 | AE24: 10.94 | AF24: =AE24/$AH$1 -> 1.8539605 | AG24: 110982.9 | AH24: =AG24/$AH$1 -> 18807.853 | AI24: 0 | AJ24: 0 | AK24: 0 | AL24: 0 | AM24: 0 | AN24: 0 | AO24: 0 | AP24: 0 | AQ24: 0 | AR24: 0 | AS24: 0 | AT24: 0 | AU24: 0 | AV24: 0 | AW24: 0 | AX24: 0 | AY24: 0 | AZ24: 0 | BA24: 0 | BB24: 0 | BC24: 0 | BD24: 0 | BE24: 0 | BF24: 0 | BG24: 0 | BH24: 0 | BI24: 0 | BJ24: 0 | BK24: 0 | BL24: 0 | BM24: =SUM(E24,J24,O24,T24,Y24,AD24,AI24,AN24,AS24,AX24,BC24,BH24) -> 10143 | BN24: =SUM(H24,M24,R24,W24,AB24,AG24,AL24,AQ24,AV24,BA24,BF24,BK24) -> 110982.9 | BO24: =SUM(I24,N24,S24,X24,AC24,AH24,AM24,AR24,AW24,BB24,BG24,BL24) -> 18807.853 | BP24: =IF(BM24=0,"",BO24/BM24) -> 1.8542692 | BQ24: Print
A25: KOEH02 / KOEHLER PAPER SE / DEU | B25: 7000463 | C25: PBM 01 8291 072 KOEH LOP | D25: 1870 | E25: 0 | F25: 0 | G25: 0 | H25: 0 | I25: 0 | J25: 0 | K25: 0 | L25: 0 | M25: 0 | N25: 0 | O25: 0 | P25: 0 | Q25: 0 | R25: 0 | S25: 0 | T25: 0 | U25: 0 | V25: 0 | W25: 0 | X25: 0 | Y25: 0 | Z25: 0 | AA25: 0 | AB25: 0 | AC25: 0 | AD25: 24967 | AE25: 11.7 | AF25: =AE25/$AH$1 -> 1.9827548 | AG25: 292055.03 | AH25: =AG25/$AH$1 -> 49493.462 | AI25: 0 | AJ25: 0 | AK25: 0 | AL25: 0 | AM25: 0 | AN25: 0 | AO25: 0 | AP25: 0 | AQ25: 0 | AR25: 0 | AS25: 0 | AT25: 0 | AU25: 0 | AV25: 0 | AW25: 0 | AX25: 0 | AY25: 0 | AZ25: 0 | BA25: 0 | BB25: 0 | BC25: 0 | BD25: 0 | BE25: 0 | BF25: 0 | BG25: 0 | BH25: 0 | BI25: 0 | BJ25: 0 | BK25: 0 | BL25: 0 | BM25: =SUM(E25,J25,O25,T25,Y25,AD25,AI25,AN25,AS25,AX25,BC25,BH25) -> 24967 | BN25: =SUM(H25,M25,R25,W25,AB25,AG25,AL25,AQ25,AV25,BA25,BF25,BK25) -> 292055.03 | BO25: =SUM(I25,N25,S25,X25,AC25,AH25,AM25,AR25,AW25,BB25,BG25,BL25) -> 49493.462 | BP25: =IF(BM25=0,"",BO25/BM25) -> 1.9823552 | BQ25: Print
A26: MALT01 / MALTA-DECOR SP. Z O. O. / POL | B26: 7000450 | C26: PBM 02 0244 065 MALT | D26: 1870 | E26: 0 | F26: 0 | G26: 0 | H26: 0 | I26: 0 | J26: 0 | K26: 0 | L26: 0 | M26: 0 | N26: 0 | O26: 60282 | P26: 15.5525 | Q26: =P26/$S$1 -> 2.572291 | R26: 937224.38 | S26: =R26/$S$1 -> 155011.34 | T26: 0 | U26: 0 | V26: 0 | W26: 0 | X26: 0 | Y26: 0 | Z26: 0 | AA26: 0 | AB26: 0 | AC26: 0 | AD26: 0 | AE26: 0 | AF26: 0 | AG26: 0 | AH26: 0 | AI26: 0 | AJ26: 0 | AK26: 0 | AL26: 0 | AM26: 0 | AN26: 0 | AO26: 0 | AP26: 0 | AQ26: 0 | AR26: 0 | AS26: 0 | AT26: 0 | AU26: 0 | AV26: 0 | AW26: 0 | AX26: 0 | AY26: 0 | AZ26: 0 | BA26: 0 | BB26: 0 | BC26: 0 | BD26: 0 | BE26: 0 | BF26: 0 | BG26: 0 | BH26: 0 | BI26: 0 | BJ26: 0 | BK26: 0 | BL26: 0 | BM26: =SUM(E26,J26,O26,T26,Y26,AD26,AI26,AN26,AS26,AX26,BC26,BH26) -> 60282 | BN26: =SUM(H26,M26,R26,W26,AB26,AG26,AL26,AQ26,AV26,BA26,BF26,BK26) -> 937224.38 | BO26: =SUM(I26,N26,S26,X26,AC26,AH26,AM26,AR26,AW26,BB26,BG26,BL26) -> 155011.34 | BP26: =IF(BM26=0,"",BO26/BM26) -> 2.5714365 | BQ26: Print
A27: MALT01 / MALTA-DECOR SP. Z O. O. / POL | B27: 7004817 | C27: PBM 02 0204 050 MALT | D27: 1870 | E27: 0 | F27: 0 | G27: 0 | H27: 0 | I27: 0 | J27: 0 | K27: 0 | L27: 0 | M27: 0 | N27: 0 | O27: 0 | P27: 0 | Q27: 0 | R27: 0 | S27: 0 | T27: 0 | U27: 0 | V27: 0 | W27: 0 | X27: 0 | Y27: 0 | Z27: 0 | AA27: 0 | AB27: 0 | AC27: 0 | AD27: 1034 | AE27: 12.84 | AF27: =AE27/$AH$1 -> 2.1759463 | AG27: 13275.07 | AH27: =AG27/$AH$1 -> 2249.676 | AI27: 0 | AJ27: 0 | AK27: 0 | AL27: 0 | AM27: 0 | AN27: 0 | AO27: 0 | AP27: 0 | AQ27: 0 | AR27: 0 | AS27: 0 | AT27: 0 | AU27: 0 | AV27: 0 | AW27: 0 | AX27: 0 | AY27: 0 | AZ27: 0 | BA27: 0 | BB27: 0 | BC27: 0 | BD27: 0 | BE27: 0 | BF27: 0 | BG27: 0 | BH27: 0 | BI27: 0 | BJ27: 0 | BK27: 0 | BL27: 0 | BM27: =SUM(E27,J27,O27,T27,Y27,AD27,AI27,AN27,AS27,AX27,BC27,BH27) -> 1034 | BN27: =SUM(H27,M27,R27,W27,AB27,AG27,AL27,AQ27,AV27,BA27,BF27,BK27) -> 13275.07 | BO27: =SUM(I27,N27,S27,X27,AC27,AH27,AM27,AR27,AW27,BB27,BG27,BL27) -> 2249.676 | BP27: =IF(BM27=0,"",BO27/BM27) -> 2.1757021 | BQ27: Print
A28: MLTV01 / VF PAPEIS S.A. / BRA | B28: 10.801 | C28: MVP FINISH FOIL BRANCO 40 G/M² 1900MM (FSC MC) | D28: 1900 | E28: 30236 | F28: 13.899908 | G28: 2.2146722 | H28: 420277.62 | I28: 66962.828 | J28: 15029 | K28: 14.103635 | L28: 2.2927233 | M28: 211963.53 | N28: 34457.338 | O28: 0 | P28: 0 | Q28: 0 | R28: 0 | S28: 0 | T28: 0 | U28: 0 | V28: 0 | W28: 0 | X28: 0 | Y28: 0 | Z28: 0 | AA28: 0 | AB28: 0 | AC28: 0 | AD28: 0 | AE28: 0 | AF28: 0 | AG28: 0 | AH28: 0 | AI28: 0 | AJ28: 0 | AK28: 0 | AL28: 0 | AM28: 0 | AN28: 0 | AO28: 0 | AP28: 0 | AQ28: 0 | AR28: 0 | AS28: 0 | AT28: 0 | AU28: 0 | AV28: 0 | AW28: 0 | AX28: 0 | AY28: 0 | AZ28: 0 | BA28: 0 | BB28: 0 | BC28: 0 | BD28: 0 | BE28: 0 | BF28: 0 | BG28: 0 | BH28: 0 | BI28: 0 | BJ28: 0 | BK28: 0 | BL28: 0 | BM28: =SUM(E28,J28,O28,T28,Y28,AD28,AI28,AN28,AS28,AX28,BC28,BH28) -> 45265 | BN28: =SUM(H28,M28,R28,W28,AB28,AG28,AL28,AQ28,AV28,BA28,BF28,BK28) -> 632241.15 | BO28: =SUM(I28,N28,S28,X28,AC28,AH28,AM28,AR28,AW28,BB28,BG28,BL28) -> 101420.17 | BP28: =IF(BM28=0,"",BO28/BM28) -> 2.2405869 | BQ28: FF
A29: MLTV01 / VF PAPEIS S.A. / BRA | B29: 10.805 | C29: MVP FINISH FOIL PARDO 40 G/M² 1900MM (FSC MC) | D29: 1900 | E29: 14324 | F29: 12.363746 | G29: 1.9699155 | H29: 177098.3 | I29: 28217.07 | J29: 30382 | K29: 12.468439 | L29: 2.0269016 | M29: 378816.11 | N29: 61581.324 | O29: 0 | P29: 0 | Q29: 0 | R29: 0 | S29: 0 | T29: 0 | U29: 0 | V29: 0 | W29: 0 | X29: 0 | Y29: 0 | Z29: 0 | AA29: 0 | AB29: 0 | AC29: 0 | AD29: 0 | AE29: 0 | AF29: 0 | AG29: 0 | AH29: 0 | AI29: 0 | AJ29: 0 | AK29: 0 | AL29: 0 | AM29: 0 | AN29: 0 | AO29: 0 | AP29: 0 | AQ29: 0 | AR29: 0 | AS29: 0 | AT29: 0 | AU29: 0 | AV29: 0 | AW29: 0 | AX29: 0 | AY29: 0 | AZ29: 0 | BA29: 0 | BB29: 0 | BC29: 0 | BD29: 0 | BE29: 0 | BF29: 0 | BG29: 0 | BH29: 0 | BI29: 0 | BJ29: 0 | BK29: 0 | BL29: 0 | BM29: =SUM(E29,J29,O29,T29,Y29,AD29,AI29,AN29,AS29,AX29,BC29,BH29) -> 44706 | BN29: =SUM(H29,M29,R29,W29,AB29,AG29,AL29,AQ29,AV29,BA29,BF29,BK29) -> 555914.41 | BO29: =SUM(I29,N29,S29,X29,AC29,AH29,AM29,AR29,AW29,BB29,BG29,BL29) -> 89798.394 | BP29: =IF(BM29=0,"",BO29/BM29) -> 2.008643 | BQ29: FF
A30: MLTV01 / VF PAPEIS S.A. / BRA | B30: 10.860 | C30: MVP FFOIL BRANCO SUPER OPACIDADE 40 G/M2 1900MM (FSC MC) | D30: 1900 | E30: 26786 | F30: 18.913534 | G30: 3.0134932 | H30: 506617.92 | I30: 80719.428 | J30: 0 | K30: 0 | L30: 0 | M30: 0 | N30: 0 | O30: 0 | P30: 0 | Q30: 0 | R30: 0 | S30: 0 | T30: 0 | U30: 0 | V30: 0 | W30: 0 | X30: 0 | Y30: 0 | Z30: 0 | AA30: 0 | AB30: 0 | AC30: 0 | AD30: 0 | AE30: 0 | AF30: 0 | AG30: 0 | AH30: 0 | AI30: 0 | AJ30: 0 | AK30: 0 | AL30: 0 | AM30: 0 | AN30: 0 | AO30: 0 | AP30: 0 | AQ30: 0 | AR30: 0 | AS30: 0 | AT30: 0 | AU30: 0 | AV30: 0 | AW30: 0 | AX30: 0 | AY30: 0 | AZ30: 0 | BA30: 0 | BB30: 0 | BC30: 0 | BD30: 0 | BE30: 0 | BF30: 0 | BG30: 0 | BH30: 0 | BI30: 0 | BJ30: 0 | BK30: 0 | BL30: 0 | BM30: =SUM(E30,J30,O30,T30,Y30,AD30,AI30,AN30,AS30,AX30,BC30,BH30) -> 26786 | BN30: =SUM(H30,M30,R30,W30,AB30,AG30,AL30,AQ30,AV30,BA30,BF30,BK30) -> 506617.92 | BO30: =SUM(I30,N30,S30,X30,AC30,AH30,AM30,AR30,AW30,BB30,BG30,BL30) -> 80719.428 | BP30: =IF(BM30=0,"",BO30/BM30) -> 3.0134932 | BQ30: FF
A31: MLTV01 / VF PAPEIS S.A. / BRA | B31: 7000470 | C31: PIP 01 9371 040 VERD HIGH OP | D31: 1900 | E31: 0 | F31: 0 | G31: 0 | H31: 0 | I31: 0 | J31: 0 | K31: 0 | L31: 0 | M31: 0 | N31: 0 | O31: 53054 | P31: 24.835 | Q31: =P31/$S$1 -> 4.1075613 | R31: 1316695.2 | S31: =R31/$S$1 -> 217773.55 | T31: 23950 | U31: 25.25 | V31: =U31/$X$1 -> 4.2869088 | W31: 604696.79 | X31: =W31/$X$1 -> 102664.55 | Y31: 0 | Z31: 0 | AA31: 0 | AB31: 0 | AC31: 0 | AD31: 0 | AE31: 0 | AF31: 0 | AG31: 0 | AH31: 0 | AI31: 0 | AJ31: 0 | AK31: 0 | AL31: 0 | AM31: 0 | AN31: 0 | AO31: 0 | AP31: 0 | AQ31: 0 | AR31: 0 | AS31: 0 | AT31: 0 | AU31: 0 | AV31: 0 | AW31: 0 | AX31: 0 | AY31: 0 | AZ31: 0 | BA31: 0 | BB31: 0 | BC31: 0 | BD31: 0 | BE31: 0 | BF31: 0 | BG31: 0 | BH31: 0 | BI31: 0 | BJ31: 0 | BK31: 0 | BL31: 0 | BM31: =SUM(E31,J31,O31,T31,Y31,AD31,AI31,AN31,AS31,AX31,BC31,BH31) -> 77004 | BN31: =SUM(H31,M31,R31,W31,AB31,AG31,AL31,AQ31,AV31,BA31,BF31,BK31) -> 1921392 | BO31: =SUM(I31,N31,S31,X31,AC31,AH31,AM31,AR31,AW31,BB31,BG31,BL31) -> 320438.1 | BP31: =IF(BM31=0,"",BO31/BM31) -> 4.1613176 | BQ31: FF
A32: MLTV01 / VF PAPEIS S.A. / BRA | B32: 7000471 | C32: PIP 01 9372 040 VERD | D32: 1900 | E32: 0 | F32: 0 | G32: 0 | H32: 0 | I32: 0 | J32: 0 | K32: 0 | L32: 0 | M32: 0 | N32: 0 | O32: 14794 | P32: 18.64 | Q32: =P32/$S$1 -> 3.0829451 | R32: 275742.7 | S32: =R32/$S$1 -> 45606.202 | T32: 30646 | U32: 18.64 | V32: =U32/$X$1 -> 3.1646725 | W32: 571205.28 | X32: =W32/$X$1 -> 96978.414 | Y32: 15407 | Z32: 18.64 | AA32: =Z32/$AC$1 -> 3.2035253 | AB32: 287168.3 | AC32: =AB32/$AC$1 -> 49353.589 | AD32: 12201 | AE32: 18.64 | AF32: 3.1588504 | AG32: 227412.24 | AH32: 38538.693 | AI32: 0 | AJ32: 0 | AK32: 0 | AL32: 0 | AM32: 0 | AN32: 0 | AO32: 0 | AP32: 0 | AQ32: 0 | AR32: 0 | AS32: 0 | AT32: 0 | AU32: 0 | AV32: 0 | AW32: 0 | AX32: 0 | AY32: 0 | AZ32: 0 | BA32: 0 | BB32: 0 | BC32: 0 | BD32: 0 | BE32: 0 | BF32: 0 | BG32: 0 | BH32: 0 | BI32: 0 | BJ32: 0 | BK32: 0 | BL32: 0 | BM32: =SUM(E32,J32,O32,T32,Y32,AD32,AI32,AN32,AS32,AX32,BC32,BH32) -> 73048 | BN32: =SUM(H32,M32,R32,W32,AB32,AG32,AL32,AQ32,AV32,BA32,BF32,BK32) -> 1361528.5 | BO32: =SUM(I32,N32,S32,X32,AC32,AH32,AM32,AR32,AW32,BB32,BG32,BL32) -> 230476.9 | BP32: =IF(BM32=0,"",BO32/BM32) -> 3.1551432 | BQ32: FF
A33: MLTV01 / VF PAPEIS S.A. / BRA | B33: 7000473 | C33: PIP 02 9374 040 VERD | D33: 1900 | E33: 0 | F33: 0 | G33: 0 | H33: 0 | I33: 0 | J33: 0 | K33: 0 | L33: 0 | M33: 0 | N33: 0 | O33: 15704 | P33: 16.25 | Q33: =P33/$S$1 -> 2.6876533 | R33: 255250.93 | S33: =R33/$S$1 -> 42216.985 | T33: 16069 | U33: 16.25 | V33: =U33/$X$1 -> 2.7589017 | W33: 261183.6 | X33: =W33/$X$1 -> 44343.377 | Y33: 0 | Z33: 0 | AA33: 0 | AB33: 0 | AC33: 0 | AD33: 0 | AE33: 0 | AF33: 0 | AG33: 0 | AH33: 0 | AI33: 0 | AJ33: 0 | AK33: 0 | AL33: 0 | AM33: 0 | AN33: 0 | AO33: 0 | AP33: 0 | AQ33: 0 | AR33: 0 | AS33: 0 | AT33: 0 | AU33: 0 | AV33: 0 | AW33: 0 | AX33: 0 | AY33: 0 | AZ33: 0 | BA33: 0 | BB33: 0 | BC33: 0 | BD33: 0 | BE33: 0 | BF33: 0 | BG33: 0 | BH33: 0 | BI33: 0 | BJ33: 0 | BK33: 0 | BL33: 0 | BM33: =SUM(E33,J33,O33,T33,Y33,AD33,AI33,AN33,AS33,AX33,BC33,BH33) -> 31773 | BN33: =SUM(H33,M33,R33,W33,AB33,AG33,AL33,AQ33,AV33,BA33,BF33,BK33) -> 516434.53 | BO33: =SUM(I33,N33,S33,X33,AC33,AH33,AM33,AR33,AW33,BB33,BG33,BL33) -> 86560.363 | BP33: =IF(BM33=0,"",BO33/BM33) -> 2.7243371 | BQ33: FF
A34: MLTV01 / VF PAPEIS S.A. / BRA | B34: 7000476 | C34: PIP 07 9377 040 VERD | D34: 1900 | E34: 0 | F34: 0 | G34: 0 | H34: 0 | I34: 0 | J34: 0 | K34: 0 | L34: 0 | M34: 0 | N34: 0 | O34: 12744 | P34: 22.08 | Q34: =P34/$S$1 -> 3.6519007 | R34: 281352.98 | S34: =R34/$S$1 -> 46534.109 | T34: 0 | U34: 0 | V34: 0 | W34: 0 | X34: 0 | Y34: 0 | Z34: 0 | AA34: 0 | AB34: 0 | AC34: 0 | AD34: 12000 | AE34: 22.08 | AF34: 3.7418142 | AG34: 264927.48 | AH34: 44896.259 | AI34: 0 | AJ34: 0 | AK34: 0 | AL34: 0 | AM34: 0 | AN34: 0 | AO34: 0 | AP34: 0 | AQ34: 0 | AR34: 0 | AS34: 0 | AT34: 0 | AU34: 0 | AV34: 0 | AW34: 0 | AX34: 0 | AY34: 0 | AZ34: 0 | BA34: 0 | BB34: 0 | BC34: 0 | BD34: 0 | BE34: 0 | BF34: 0 | BG34: 0 | BH34: 0 | BI34: 0 | BJ34: 0 | BK34: 0 | BL34: 0 | BM34: =SUM(E34,J34,O34,T34,Y34,AD34,AI34,AN34,AS34,AX34,BC34,BH34) -> 24744 | BN34: =SUM(H34,M34,R34,W34,AB34,AG34,AL34,AQ34,AV34,BA34,BF34,BK34) -> 546280.46 | BO34: =SUM(I34,N34,S34,X34,AC34,AH34,AM34,AR34,AW34,BB34,BG34,BL34) -> 91430.368 | BP34: =IF(BM34=0,"",BO34/BM34) -> 3.6950521 | BQ34: FF
A35: MUNK01 / MUNKSJO UNTERKOCHEN GMBH / DEU | B35: 7002370 | C35: PBM 02 0301 065 MUNK | D35: 1870 | E35: 0 | F35: 0 | G35: 0 | H35: 0 | I35: 0 | J35: 0 | K35: 0 | L35: 0 | M35: 0 | N35: 0 | O35: 0 | P35: 0 | Q35: 0 | R35: 0 | S35: 0 | T35: 0 | U35: 0 | V35: =U35/$X$1 -> 0 | W35: 0 | X35: =W35/$X$1 -> 0 | Y35: 25408 | Z35: 13.01 | AA35: =Z35/$AC$1 -> 2.2359369 | AB35: 330610.17 | AC35: =AB35/$AC$1 -> 56819.637 | AD35: 0 | AE35: 0 | AF35: 0 | AG35: 0 | AH35: 0 | AI35: 0 | AJ35: 0 | AK35: 0 | AL35: 0 | AM35: 0 | AN35: 0 | AO35: 0 | AP35: 0 | AQ35: 0 | AR35: 0 | AS35: 0 | AT35: 0 | AU35: 0 | AV35: 0 | AW35: 0 | AX35: 0 | AY35: 0 | AZ35: 0 | BA35: 0 | BB35: 0 | BC35: 0 | BD35: 0 | BE35: 0 | BF35: 0 | BG35: 0 | BH35: 0 | BI35: 0 | BJ35: 0 | BK35: 0 | BL35: 0 | BM35: =SUM(E35,J35,O35,T35,Y35,AD35,AI35,AN35,AS35,AX35,BC35,BH35) -> 25408 | BN35: =SUM(H35,M35,R35,W35,AB35,AG35,AL35,AQ35,AV35,BA35,BF35,BK35) -> 330610.17 | BO35: =SUM(I35,N35,S35,X35,AC35,AH35,AM35,AR35,AW35,BB35,BG35,BL35) -> 56819.637 | BP35: =IF(BM35=0,"",BO35/BM35) -> 2.2362892 | BQ35: Print
A36: MUNK01 / MUNKSJO UNTERKOCHEN GMBH / DEU | B36: 7002370 | C36: PBM 02 0301 065 MUNK | D36: 2175 | E36: 0 | F36: 0 | G36: 0 | H36: 0 | I36: 0 | J36: 0 | K36: 0 | L36: 0 | M36: 0 | N36: 0 | O36: 0 | P36: 0 | Q36: 0 | R36: 0 | S36: 0 | T36: 0 | U36: 0 | V36: =U36/$X$1 -> 0 | W36: 0 | X36: =W36/$X$1 -> 0 | Y36: 10854 | Z36: 13.01 | AA36: =Z36/$AC$1 -> 2.2359369 | AB36: 141232.79 | AC36: =AB36/$AC$1 -> 24272.683 | AD36: 0 | AE36: 0 | AF36: 0 | AG36: 0 | AH36: 0 | AI36: 0 | AJ36: 0 | AK36: 0 | AL36: 0 | AM36: 0 | AN36: 0 | AO36: 0 | AP36: 0 | AQ36: 0 | AR36: 0 | AS36: 0 | AT36: 0 | AU36: 0 | AV36: 0 | AW36: 0 | AX36: 0 | AY36: 0 | AZ36: 0 | BA36: 0 | BB36: 0 | BC36: 0 | BD36: 0 | BE36: 0 | BF36: 0 | BG36: 0 | BH36: 0 | BI36: 0 | BJ36: 0 | BK36: 0 | BL36: 0 | BM36: =SUM(E36,J36,O36,T36,Y36,AD36,AI36,AN36,AS36,AX36,BC36,BH36) -> 10854 | BN36: =SUM(H36,M36,R36,W36,AB36,AG36,AL36,AQ36,AV36,BA36,BF36,BK36) -> 141232.79 | BO36: =SUM(I36,N36,S36,X36,AC36,AH36,AM36,AR36,AW36,BB36,BG36,BL36) -> 24272.683 | BP36: =IF(BM36=0,"",BO36/BM36) -> 2.2362892 | BQ36: Print
A37: MUNK04 / MUNKSJO PAPER S/A DETTINGEN / DEU | B37: 7000469 | C37: PIP 01 9370 070 MUNK PO NEW WHITE | D37: 1880 | E37: 0 | F37: 0 | G37: 0 | H37: 0 | I37: 0 | J37: 0 | K37: 0 | L37: 0 | M37: 0 | N37: 0 | O37: 38638 | P37: 16.09 | Q37: =P37/$S$1 -> 2.6611903 | R37: 621616.34 | S37: =R37/$S$1 -> 102811.64 | T37: 95470 | U37: 15.62 | V37: =U37/$X$1 -> 2.6519412 | W37: 1491347.9 | X37: =W37/$X$1 -> 253198.92 | Y37: 48397 | Z37: 15.06 | AA37: =Z37/$AC$1 -> 2.5882559 | AB37: 729092.67 | AC37: =AB37/$AC$1 -> 125304.01 | AD37: 24241 | AE37: 15.50177 | AF37: =AE37/$AH$1 -> 2.6270263 | AG37: 375778.4 | AH37: =AG37/$AH$1 -> 63681.746 | AI37: 0 | AJ37: 0 | AK37: 0 | AL37: 0 | AM37: 0 | AN37: 0 | AO37: 0 | AP37: 0 | AQ37: 0 | AR37: 0 | AS37: 0 | AT37: 0 | AU37: 0 | AV37: 0 | AW37: 0 | AX37: 0 | AY37: 0 | AZ37: 0 | BA37: 0 | BB37: 0 | BC37: 0 | BD37: 0 | BE37: 0 | BF37: 0 | BG37: 0 | BH37: 0 | BI37: 0 | BJ37: 0 | BK37: 0 | BL37: 0 | BM37: =SUM(E37,J37,O37,T37,Y37,AD37,AI37,AN37,AS37,AX37,BC37,BH37) -> 206746 | BN37: =SUM(H37,M37,R37,W37,AB37,AG37,AL37,AQ37,AV37,BA37,BF37,BK37) -> 3217835.4 | BO37: =SUM(I37,N37,S37,X37,AC37,AH37,AM37,AR37,AW37,BB37,BG37,BL37) -> 544996.32 | BP37: =IF(BM37=0,"",BO37/BM37) -> 2.636067 | BQ37: FF
A38: MUNK04 / MUNKSJO PAPER S/A DETTINGEN / DEU | B38: 10.255 | C38: MUNKSJO 9370-070 PO MFOIL WHITE 70G/M² 1880MM (FSC MC) | D38: 1880 | E38: 46994 | F38: 20.444538 | G38: 3.257428 | H38: 960770.62 | I38: 153079.57 | J38: 0 | K38: 0 | L38: 0 | M38: 0 | N38: 0 | O38: 0 | P38: 0 | Q38: 0 | R38: 0 | S38: 0 | T38: 0 | U38: 0 | V38: 0 | W38: 0 | X38: 0 | Y38: 0 | Z38: 0 | AA38: 0 | AB38: 0 | AC38: 0 | AD38: 0 | AE38: 0 | AF38: 0 | AG38: 0 | AH38: 0 | AI38: 0 | AJ38: 0 | AK38: 0 | AL38: 0 | AM38: 0 | AN38: 0 | AO38: 0 | AP38: 0 | AQ38: 0 | AR38: 0 | AS38: 0 | AT38: 0 | AU38: 0 | AV38: 0 | AW38: 0 | AX38: 0 | AY38: 0 | AZ38: 0 | BA38: 0 | BB38: 0 | BC38: 0 | BD38: 0 | BE38: 0 | BF38: 0 | BG38: 0 | BH38: 0 | BI38: 0 | BJ38: 0 | BK38: 0 | BL38: 0 | BM38: =SUM(E38,J38,O38,T38,Y38,AD38,AI38,AN38,AS38,AX38,BC38,BH38) -> 46994 | BN38: =SUM(H38,M38,R38,W38,AB38,AG38,AL38,AQ38,AV38,BA38,BF38,BK38) -> 960770.62 | BO38: =SUM(I38,N38,S38,X38,AC38,AH38,AM38,AR38,AW38,BB38,BG38,BL38) -> 153079.57 | BP38: =IF(BM38=0,"",BO38/BM38) -> 3.257428 | BQ38: FF
A39: MUNK04 / MUNKSJO PAPER S/A DETTINGEN / DEU | B39: 7000466 | C39: PIP 01 9370 070 MUNK PO MFOIL | D39: 1880 | E39: 0 | F39: 0 | G39: 0 | H39: 0 | I39: 0 | J39: 0 | K39: 0 | L39: 0 | M39: 0 | N39: 0 | O39: 9768 | P39: 17.78 | Q39: =P39/$S$1 -> 2.9407062 | R39: 173691.72 | S39: =R39/$S$1 -> 28727.577 | T39: 0 | U39: 0 | V39: 0 | W39: 0 | X39: 0 | Y39: 0 | Z39: 0 | AA39: 0 | AB39: 0 | AC39: 0 | AD39: 0 | AE39: 0 | AF39: 0 | AG39: 0 | AH39: 0 | AI39: 0 | AJ39: 0 | AK39: 0 | AL39: 0 | AM39: 0 | AN39: 0 | AO39: 0 | AP39: 0 | AQ39: 0 | AR39: 0 | AS39: 0 | AT39: 0 | AU39: 0 | AV39: 0 | AW39: 0 | AX39: 0 | AY39: 0 | AZ39: 0 | BA39: 0 | BB39: 0 | BC39: 0 | BD39: 0 | BE39: 0 | BF39: 0 | BG39: 0 | BH39: 0 | BI39: 0 | BJ39: 0 | BK39: 0 | BL39: 0 | BM39: =SUM(E39,J39,O39,T39,Y39,AD39,AI39,AN39,AS39,AX39,BC39,BH39) -> 9768 | BN39: =SUM(H39,M39,R39,W39,AB39,AG39,AL39,AQ39,AV39,BA39,BF39,BK39) -> 173691.72 | BO39: =SUM(I39,N39,S39,X39,AC39,AH39,AM39,AR39,AW39,BB39,BG39,BL39) -> 28727.577 | BP39: =IF(BM39=0,"",BO39/BM39) -> 2.9409887 | BQ39: FF
A40: MUNK04 / MUNKSJO PAPER S/A DETTINGEN / DEU | B40: 7002366 | C40: DPU 07 0080 080 MUNK | D40: 1860 | E40: 0 | F40: 0 | G40: 0 | H40: 0 | I40: 0 | J40: 0 | K40: 0 | L40: 0 | M40: 0 | N40: 0 | O40: 0 | P40: 0 | Q40: 0 | R40: 0 | S40: 0 | T40: 0 | U40: 0 | V40: 0 | W40: 0 | X40: 0 | Y40: 0 | Z40: 0 | AA40: 0 | AB40: 0 | AC40: 0 | AD40: 818 | AE40: 16.37 | AF40: =AE40/$AH$1 -> 2.7741621 | AG40: 13390.09 | AH40: =AG40/$AH$1 -> 2269.168 | AI40: 0 | AJ40: 0 | AK40: 0 | AL40: 0 | AM40: 0 | AN40: 0 | AO40: 0 | AP40: 0 | AQ40: 0 | AR40: 0 | AS40: 0 | AT40: 0 | AU40: 0 | AV40: 0 | AW40: 0 | AX40: 0 | AY40: 0 | AZ40: 0 | BA40: 0 | BB40: 0 | BC40: 0 | BD40: 0 | BE40: 0 | BF40: 0 | BG40: 0 | BH40: 0 | BI40: 0 | BJ40: 0 | BK40: 0 | BL40: 0 | BM40: =SUM(E40,J40,O40,T40,Y40,AD40,AI40,AN40,AS40,AX40,BC40,BH40) -> 818 | BN40: =SUM(H40,M40,R40,W40,AB40,AG40,AL40,AQ40,AV40,BA40,BF40,BK40) -> 13390.09 | BO40: =SUM(I40,N40,S40,X40,AC40,AH40,AM40,AR40,AW40,BB40,BG40,BL40) -> 2269.168 | BP40: =IF(BM40=0,"",BO40/BM40) -> 2.774044 | BQ40: IP | BR40: uni
...

Sheet PAPER BASE
A1: Plant | B1: Supplier name | C1: Product Group | D1: Material nr | E1: Mat Description | F1: Width (mm) | G1: Quantity KG | H1: Value EUR | I1: Month.Year | J1: Material Group | O1: Product Group List
A2: =IF(B2<>"","Curitiba","") -> Curitiba | B2: =_xlfn.XLOOKUP(D2,Reunido!B:B,Reunido!A:A,"",0) -> MUNK09 / MUNKSJO CAIEIRAS LTDA / BRA | C2: =IF(D2<>0,IF(_xlfn.XLOOKUP(D2,Reunido!B:B,Reunido!BQ:BQ,"",0)="Print",$O$2,IF(_xlfn.XLOOKUP(D2,Reunido!B:B,Reunido!BQ:BQ,"",0)="IP",$O$3,IF(_xlfn.XLOOKUP(D2,Reunido!B:B,Reunido!BQ:BQ,"",0)="FF",$O$4,""))),"") -> Impregnated Papers | D2: 15.432 | E2: DEKORPRINT BEIGE 752 68G/M2 1870MM TYPE2638 (FSC MC) | F2: 1870 | G2: {=_xlfn.XLOOKUP(D2&F2,Reunido!B:B&Reunido!D:D,Reunido!E:E,"",1)} -> 25502 | H2: {=_xlfn.XLOOKUP(D2&F2,Reunido!B:B&Reunido!D:D,Reunido!I:I,"",1)} -> 71146.879 | I2: 46023 | J2: =C2 -> Impregnated Papers | O2: Decorative Papers
A3: =IF(B3<>"","Curitiba","") -> Curitiba | B3: =_xlfn.XLOOKUP(D3,Reunido!B:B,Reunido!A:A,"",0) -> MUNK09 / MUNKSJO CAIEIRAS LTDA / BRA | C3: =IF(D3<>0,IF(_xlfn.XLOOKUP(D3,Reunido!B:B,Reunido!BQ:BQ,"",0)="Print",$O$2,IF(_xlfn.XLOOKUP(D3,Reunido!B:B,Reunido!BQ:BQ,"",0)="IP",$O$3,IF(_xlfn.XLOOKUP(D3,Reunido!B:B,Reunido!BQ:BQ,"",0)="FF",$O$4,""))),"") -> Impregnated Papers | D3: 16.004 | E3: DEKORPEL BEIGE 9080 80G/M2 1855MM (FSC MC) | F3: 1855 | G3: {=_xlfn.XLOOKUP(D3&F3,Reunido!B:B&Reunido!D:D,Reunido!E:E,"",1)} -> 4352 | H3: {=_xlfn.XLOOKUP(D3&F3,Reunido!B:B&Reunido!D:D,Reunido!I:I,"",1)} -> 12729.936 | I3: 46023 | J3: =C3 -> Impregnated Papers | O3: Impregnated Papers
A4: =IF(B4<>"","Curitiba","") -> Curitiba | B4: =_xlfn.XLOOKUP(D4,Reunido!B:B,Reunido!A:A,"",0) -> MUNK09 / MUNKSJO CAIEIRAS LTDA / BRA | C4: =IF(D4<>0,IF(_xlfn.XLOOKUP(D4,Reunido!B:B,Reunido!BQ:BQ,"",0)="Print",$O$2,IF(_xlfn.XLOOKUP(D4,Reunido!B:B,Reunido!BQ:BQ,"",0)="IP",$O$3,IF(_xlfn.XLOOKUP(D4,Reunido!B:B,Reunido!BQ:BQ,"",0)="FF",$O$4,""))),"") -> Impregnated Papers | D4: 16.068 | E4: DEKORPEL WHITE 963 78G/M2 1855MM (FSC MC) | F4: 1855 | G4: {=_xlfn.XLOOKUP(D4&F4,Reunido!B:B&Reunido!D:D,Reunido!E:E,"",1)} -> 47661 | H4: {=_xlfn.XLOOKUP(D4&F4,Reunido!B:B&Reunido!D:D,Reunido!I:I,"",1)} -> 106351.25 | I4: 46023 | J4: =C4 -> Impregnated Papers | O4: Finish Foils
